Workbook

Sheet Details
A1: Subject | B1: Securities Analysis and Portfolio Management
A2: Topic: | B2: Risk and Return Analysis of 5 NIFTY50 Stocks using Markowitz Model and Single Index Model
A3: By: | B3: Abhimanyu Babbar

Sheet Alpha - Beta Computation
A1: Alpha-Beta Computation
A3: Date | B3: NIFTY50 | C3: NTPC | D3: Dabur India | E3: HDFC Life Insurance | F3: Adani Enterprises | G3: Hindalco Industries | I3: Using Excel Function | J3: =C3 -> NTPC | K3: =D3 -> Dabur India | L3: =E3 -> HDFC Life Insurance | M3: =F3 -> Adani Enterprises | N3: =G3 -> Hindalco Industries
A4: 45499 | B4: ='NIFTY 50'!C2 -> 0 | C4: =NTPC!D2 -> 0 | D4: ='Dabur India'!D2 -> 0 | E4: ='HDFC Life Insurance'!D2 -> 0 | F4: ='Adani Enterprises'!D2 -> 0 | G4: ='Hindalco Industries'!D2 -> 0 | I4: Alpha (Intercept) | J4: =INTERCEPT(C4:C253,$B$4:$B$253) -> -0.0006940993 | K4: =INTERCEPT(D4:D253,$B$4:$B$253) -> -0.00085039631 | L4: =INTERCEPT(E4:E253,$B$4:$B$253) -> 0.00020020086 | M4: =INTERCEPT(F4:F253,$B$4:$B$253) -> -0.00075638371 | N4: =INTERCEPT(G4:G253,$B$4:$B$253) -> 0.00015150524
A5: 45502 | B5: ='NIFTY 50'!C3 -> 5.033123e-05 | C5: =NTPC!D3 -> -0.0060744302 | D5: ='Dabur India'!D3 -> 0.013584285 | E5: ='HDFC Life Insurance'!D3 -> -0.0092844546 | F5: ='Adani Enterprises'!D3 -> 0.0028687913 | G5: ='Hindalco Industries'!D3 -> -0.0011240587 | I5: Beta (Slope) | J5: =SLOPE(C4:C253,$B$4:$B$253) -> 1.1116739 | K5: =SLOPE(D4:D253,$B$4:$B$253) -> 0.60298073 | L5: =SLOPE(E4:E253,$B$4:$B$253) -> 0.80206706 | M5: =SLOPE(F4:F253,$B$4:$B$253) -> 1.5777153 | N5: =SLOPE(G4:G253,$B$4:$B$253) -> 1.3126941
A6: 45503 | B6: ='NIFTY 50'!C4 -> 0.00085323207 | C6: =NTPC!D4 -> 0.032593258 | D6: ='Dabur India'!D4 -> -0.011294238 | E6: ='HDFC Life Insurance'!D4 -> 0.00050213408 | F6: ='Adani Enterprises'!D4 -> 0.012672851 | G6: ='Hindalco Industries'!D4 -> -0.0095680091
A7: 45504 | B7: ='NIFTY 50'!C5 -> 0.0037684413 | C7: =NTPC!D5 -> 0.021994932 | D7: ='Dabur India'!D5 -> 0.0028355407 | E7: ='HDFC Life Insurance'!D5 -> 0.025909285 | F7: ='Adani Enterprises'!D5 -> 0.012908732 | G7: ='Hindalco Industries'!D5 -> 0.013683395 | J7: =INTERCEPT(C2:C251,$B$2:$B$251)
A8: 45505 | B8: ='NIFTY 50'!C6 -> 0.0023918165 | C8: =NTPC!D6 -> 0.017750183 | D8: ='Dabur India'!D6 -> 0.012195273 | E8: ='HDFC Life Insurance'!D6 -> -0.0026590177 | F8: ='Adani Enterprises'!D6 -> 0.014984662 | G8: ='Hindalco Industries'!D6 -> 0.0058074767 | J8: =SLOPE(C2:C251,$B$2:$B$251)
A9: 45506 | B9: ='NIFTY 50'!C7 -> -0.011792144 | C9: =NTPC!D7 -> -0.008895273 | D9: ='Dabur India'!D7 -> -0.025098678 | E9: ='HDFC Life Insurance'!D7 -> -0.0087263045 | F9: ='Adani Enterprises'!D7 -> -0.01767016 | G9: ='Hindalco Industries'!D7 -> -0.038520142
A10: 45509 | B10: ='NIFTY 50'!C8 -> -0.027151769 | C10: =NTPC!D8 -> -0.015487434 | D10: ='Dabur India'!D8 -> 0.010225605 | E10: ='HDFC Life Insurance'!D8 -> 0.0049354962 | F10: ='Adani Enterprises'!D8 -> -0.039591562 | G10: ='Hindalco Industries'!D8 -> -0.053484446 | I10: Using Regression - Data Analysis Toolpak | J10: =J3 -> NTPC | K10: =K3 -> Dabur India | L10: =L3 -> HDFC Life Insurance | M10: =M3 -> Adani Enterprises | N10: =N3 -> Hindalco Industries
A11: 45510 | B11: ='NIFTY 50'!C9 -> -0.0026244522 | C11: =NTPC!D9 -> 0.0042257835 | D11: ='Dabur India'!D9 -> -0.0076792524 | E11: ='HDFC Life Insurance'!D9 -> -0.045027383 | F11: ='Adani Enterprises'!D9 -> 0.011291419 | G11: ='Hindalco Industries'!D9 -> -0.0065327686 | I11: Alpha (Intercept) | J11: =Regression!B17 -> -0.0006940993 | K11: =Regression!L17 -> -0.00085039631 | L11: =Regression!B37 -> 0.00020020086 | M11: =Regression!L37 -> -0.00075638371 | N11: =Regression!B58 -> 0.00015150524
A12: 45511 | B12: ='NIFTY 50'!C10 -> 0.012630099 | C12: =NTPC!D10 -> 0.003127634 | D12: ='Dabur India'!D10 -> 0.015925912 | E12: ='HDFC Life Insurance'!D10 -> 0.024204401 | F12: ='Adani Enterprises'!D10 -> 0.036193864 | G12: ='Hindalco Industries'!D10 -> 0.021718844 | I12: Beta (Slope) | J12: =Regression!B18 -> 1.1116739 | K12: =Regression!L18 -> 0.60298073 | L12: =Regression!B38 -> 0.80206706 | M12: =Regression!L38 -> 1.5777153 | N12: =Regression!B59 -> 1.3126941
A13: 45512 | B13: ='NIFTY 50'!C11 -> -0.0074564784 | C13: =NTPC!D11 -> -0.020874544 | D13: ='Dabur India'!D11 -> -0.0028197716 | E13: ='HDFC Life Insurance'!D11 -> 0.020049015 | F13: ='Adani Enterprises'!D11 -> -0.0057920993 | G13: ='Hindalco Industries'!D11 -> -0.015593125
A14: 45513 | B14: ='NIFTY 50'!C12 -> 0.010333291 | C14: =NTPC!D12 -> 0.0072096604 | D14: ='Dabur India'!D12 -> -0.021405606 | E14: ='HDFC Life Insurance'!D12 -> -0.011254764 | F14: ='Adani Enterprises'!D12 -> 0.0062941782 | G14: ='Hindalco Industries'!D12 -> 0.014309634
A15: 45516 | B15: ='NIFTY 50'!C13 -> -0.00084163858 | C15: =NTPC!D13 -> -0.024153978 | D15: ='Dabur India'!D13 -> -0.0057864021 | E15: ='HDFC Life Insurance'!D13 -> 7.1181977e-05 | F15: ='Adani Enterprises'!D13 -> -0.011294743 | G15: ='Hindalco Industries'!D13 -> 0.010301548 | I15: Difference (Intercept) | J15: =J4-J11 -> 0 | K15: =K4-K11 -> 0 | L15: =L4-L11 -> 0 | M15: =M4-M11 -> 0 | N15: =N4-N11 -> 0
A16: 45517 | B16: ='NIFTY 50'!C14 -> -0.0085798489 | C16: =NTPC!D14 -> -0.011668158 | D16: ='Dabur India'!D14 -> -0.023651404 | E16: ='HDFC Life Insurance'!D14 -> -0.025155386 | F16: ='Adani Enterprises'!D14 -> -0.019075042 | G16: ='Hindalco Industries'!D14 -> -0.012712544 | I16: Difference (Slope) | J16: =J5-J12 -> 0 | K16: =K5-K12 -> 0 | L16: =L5-L12 -> 0 | M16: =M5-M12 -> 0 | N16: =N5-N12 -> 0
A17: 45518 | B17: ='NIFTY 50'!C15 -> 0.00019675764 | C17: =NTPC!D15 -> 0.00037852502 | D17: ='Dabur India'!D15 -> -0.0023962003 | E17: ='HDFC Life Insurance'!D15 -> 0.0019688634 | F17: ='Adani Enterprises'!D15 -> -0.016992402 | G17: ='Hindalco Industries'!D15 -> 8.0460233e-05
A18: 45520 | B18: ='NIFTY 50'!C16 -> 0.016325753 | C18: =NTPC!D16 -> 0.0042799663 | D18: ='Dabur India'!D16 -> 0.021604768 | E18: ='HDFC Life Insurance'!D16 -> 0.0044339524 | F18: ='Adani Enterprises'!D16 -> 0.02234639 | G18: ='Hindalco Industries'!D16 -> 0.020230062
A19: 45523 | B19: ='NIFTY 50'!C17 -> 0.0012827354 | C19: =NTPC!D17 -> 0.012607045 | D19: ='Dabur India'!D17 -> 0.0059730584 | E19: ='HDFC Life Insurance'!D17 -> -0.0053814398 | F19: ='Adani Enterprises'!D17 -> -0.0020124456 | G19: ='Hindalco Industries'!D17 -> 0.038210371 | J19: NIFTY50 | K19: NTPC | L19: Dabur India | M19: HDFC Life Insurance | N19: Adani Enterprises | O19: Hindalco Industries
A20: 45524 | B20: ='NIFTY 50'!C18 -> 0.005122648 | C20: =NTPC!D18 -> 0.0077840635 | D20: ='Dabur India'!D18 -> 0.0028929625 | E20: ='HDFC Life Insurance'!D18 -> 0.035669469 | F20: ='Adani Enterprises'!D18 -> -0.010335088 | G20: ='Hindalco Industries'!D18 -> 0.021100839 | I20: NIFTY50 | J20: 1
A21: 45525 | B21: ='NIFTY 50'!C19 -> 0.0028846339 | C21: =NTPC!D19 -> 0.0066241655 | D21: ='Dabur India'!D19 -> 0.017893833 | E21: ='HDFC Life Insurance'!D19 -> 0.019441089 | F21: ='Adani Enterprises'!D19 -> 0.014564581 | G21: ='Hindalco Industries'!D19 -> 0.018697637 | I21: NTPC | J21: 0.53467522 | K21: 1
A22: 45526 | B22: ='NIFTY 50'!C20 -> 0.0016659376 | C22: =NTPC!D20 -> -0.013788228 | D22: ='Dabur India'!D20 -> 0.018430822 | E22: ='HDFC Life Insurance'!D20 -> 0.0019992423 | F22: ='Adani Enterprises'!D20 -> -0.0053582332 | G22: ='Hindalco Industries'!D20 -> -7.2931481e-05 | I22: Dabur India | J22: 0.41628688 | K22: 0.75328724 | L22: 1
A23: 45527 | B23: ='NIFTY 50'!C21 -> 0.00046943013 | C23: =NTPC!D21 -> -0.0034769686 | D23: ='Dabur India'!D21 -> -0.0044982238 | E23: ='HDFC Life Insurance'!D21 -> 0.0041237172 | F23: ='Adani Enterprises'!D21 -> -0.0073517836 | G23: ='Hindalco Industries'!D21 -> -0.00065662279 | I23: HDFC Life Insurance | J23: 0.75538372 | K23: 0.32294721 | L23: 0.063422427 | M23: 1
A24: 45530 | B24: ='NIFTY 50'!C22 -> 0.0075230495 | C24: =NTPC!D22 -> 0.031589306 | D24: ='Dabur India'!D22 -> 0.017414525 | E24: ='HDFC Life Insurance'!D22 -> -0.0046059271 | F24: ='Adani Enterprises'!D22 -> -0.0023920537 | G24: ='Hindalco Industries'!D22 -> 0.038302402 | I24: Adani Enterprises | J24: 0.65975558 | K24: 0.88425693 | L24: 0.79214576 | M24: 0.42782349 | N24: 1
A25: 45531 | B25: ='NIFTY 50'!C23 -> 0.00028583793 | C25: =NTPC!D23 -> -0.012613873 | D25: ='Dabur India'!D23 -> -0.017181362 | E25: ='HDFC Life Insurance'!D23 -> 0.018974088 | F25: ='Adani Enterprises'!D23 -> -0.00061928589 | G25: ='Hindalco Industries'!D23 -> -0.011799339 | I25: Hindalco Industries | J25: 0.57432852 | K25: 0.62597246 | L25: 0.35794412 | M25: 0.48507367 | N25: 0.5415577 | O25: 1
A26: 45532 | B26: ='NIFTY 50'!C24 -> 0.0013820626 | C26: =NTPC!D24 -> -0.0014657386 | D26: ='Dabur India'!D24 -> 0.0015530365 | E26: ='HDFC Life Insurance'!D24 -> 0.0034421119 | F26: ='Adani Enterprises'!D24 -> -0.012830154 | G26: ='Hindalco Industries'!D24 -> 0.0022008457
A27: 45533 | B27: ='NIFTY 50'!C25 -> 0.0039677928 | C27: =NTPC!D25 -> 0.0020758296 | D27: ='Dabur India'!D25 -> -0.00038803307 | E27: ='HDFC Life Insurance'!D25 -> -0.0070318072 | F27: ='Adani Enterprises'!D25 -> -0.0025958365 | G27: ='Hindalco Industries'!D25 -> -0.0064743565 | I27: Used correlation from data analysis toolpak.
A28: 45534 | B28: ='NIFTY 50'!C26 -> 0.0033321556 | C28: =NTPC!D26 -> 0.015252686 | D28: ='Dabur India'!D26 -> -0.010926512 | E28: ='HDFC Life Insurance'!D26 -> 0.0024396868 | F28: ='Adani Enterprises'!D26 -> -0.00026492259 | G28: ='Hindalco Industries'!D26 -> 0.0012126834
A29: 45537 | B29: ='NIFTY 50'!C27 -> 0.00169456 | C29: =NTPC!D27 -> -0.015008754 | D29: ='Dabur India'!D27 -> -0.00078505264 | E29: ='HDFC Life Insurance'!D27 -> 0.0088949374 | F29: ='Adani Enterprises'!D27 -> 0.0075229259 | G29: ='Hindalco Industries'!D27 -> -0.025195341
A30: 45538 | B30: ='NIFTY 50'!C28 -> 4.5491811e-05 | C30: =NTPC!D28 -> -0.0088192634 | D30: ='Dabur India'!D28 -> 0.0024316598 | E30: ='HDFC Life Insurance'!D28 -> 0.01788552 | F30: ='Adani Enterprises'!D28 -> -0.0019907052 | G30: ='Hindalco Industries'!D28 -> -0.0073378668
A31: 45539 | B31: ='NIFTY 50'!C29 -> -0.0032152298 | C31: =NTPC!D29 -> -0.0032039461 | D31: ='Dabur India'!D29 -> 0.018397569 | E31: ='HDFC Life Insurance'!D29 -> 6.5895687e-05 | F31: ='Adani Enterprises'!D29 -> -0.007853292 | G31: ='Hindalco Industries'!D29 -> -0.01798369
A32: 45540 | B32: ='NIFTY 50'!C30 -> -0.0021293593 | C32: =NTPC!D30 -> -0.0045772332 | D32: ='Dabur India'!D30 -> -0.0081090918 | E32: ='HDFC Life Insurance'!D30 -> -0.0092014021 | F32: ='Adani Enterprises'!D30 -> 0.00099540463 | G32: ='Hindalco Industries'!D30 -> 0.0047129319
A33: 45541 | B33: ='NIFTY 50'!C31 -> -0.011718779 | C33: =NTPC!D31 -> -0.021177409 | D33: ='Dabur India'!D31 -> -0.00062053989 | E33: ='HDFC Life Insurance'!D31 -> -0.018051153 | F33: ='Adani Enterprises'!D31 -> -0.013320622 | G33: ='Hindalco Industries'!D31 -> -0.004263123
A34: 45544 | B34: ='NIFTY 50'!C32 -> 0.0033843155 | C34: =NTPC!D32 -> -0.012617258 | D34: ='Dabur India'!D32 -> 0.027474466 | E34: ='HDFC Life Insurance'!D32 -> -0.0035273405 | F34: ='Adani Enterprises'!D32 -> -0.0038049746 | G34: ='Hindalco Industries'!D32 -> -0.012899511
A35: 45545 | B35: ='NIFTY 50'!C33 -> 0.0041898916 | C35: =NTPC!D33 -> 0.01640945 | D35: ='Dabur India'!D33 -> 0.0043687927 | E35: ='HDFC Life Insurance'!D33 -> -0.045743708 | F35: ='Adani Enterprises'!D33 -> 0.0074783352 | G35: ='Hindalco Industries'!D33 -> 0.0014415237
A36: 45546 | B36: ='NIFTY 50'!C34 -> -0.004909982 | C36: =NTPC!D34 -> -0.0169226 | D36: ='Dabur India'!D34 -> -0.0020313741 | E36: ='HDFC Life Insurance'!D34 -> -0.0039200364 | F36: ='Adani Enterprises'!D34 -> -0.016390627 | G36: ='Hindalco Industries'!D34 -> -0.018054346
A37: 45547 | B37: ='NIFTY 50'!C35 -> 0.018703578 | C37: =NTPC!D35 -> 0.038267728 | D37: ='Dabur India'!D35 -> 0.0012794944 | E37: ='HDFC Life Insurance'!D35 -> 0.020358376 | F37: ='Adani Enterprises'!D35 -> 0.017929758 | G37: ='Hindalco Industries'!D35 -> 0.043061264
A38: 45548 | B38: ='NIFTY 50'!C36 -> -0.0012769632 | C38: =NTPC!D36 -> -0.0085581918 | D38: ='Dabur India'!D36 -> -0.0058084876 | E38: ='HDFC Life Insurance'!D36 -> -0.012887956 | F38: ='Adani Enterprises'!D36 -> -0.0076015368 | G38: ='Hindalco Industries'!D36 -> -0.0043721586
A39: 45551 | B39: ='NIFTY 50'!C37 -> 0.0010740981 | C39: =NTPC!D37 -> 0.023878058 | D39: ='Dabur India'!D37 -> 0.000680658 | E39: ='HDFC Life Insurance'!D37 -> -0.0057579686 | F39: ='Adani Enterprises'!D37 -> 0.0055600026 | G39: ='Hindalco Industries'!D37 -> 0.017521061
... A253: 45863 | B253: ='NIFTY 50'!C251 -> -0.009022268 | C253: =NTPC!D251 -> -0.016962168 | D253: ='Dabur India'!D251 -> -0.00234398 | E253: ='HDFC Life Insurance'!D251 -> -0.030431486 | F253: ='Adani Enterprises'!D251 -> -0.022604432 | G253: ='Hindalco Industries'!D251 -> -0.0030956434

Sheet Markowitz Model
A1: Markowitz Model
A3: Company | B3: Expected Returns (Individual) | C3: Standard Deviation (Individual) | D3: Weights | H3: NIFTY50 | I3: NTPC | J3: Dabur India | K3: HDFC Life Insurance | L3: Adani Enterprises | M3: Hindalco Industries
A4: NTPC | B4: =NTPC!H4 -> -0.17481602 | C4: =NTPC!H5 -> 0.038849481 | D4: =1/5 -> 0.2 | G4: NIFTY50 | H4: 1
A5: Dabur India | B5: ='Dabur India'!H4 -> -0.21424725 | C5: ='Dabur India'!H5 -> 0.033880841 | D5: =1/5 -> 0.2 | G5: NTPC | H5: 0.53467522 | I5: 1
A6: HDFC Life Insurance | B6: ='HDFC Life Insurance'!H4 -> 0.050520605 | C6: ='HDFC Life Insurance'!H5 -> 0.036916119 | D6: =1/5 -> 0.2 | G6: Dabur India | H6: 0.41628688 | I6: 0.75328724 | J6: 1
A7: Adani Enterprises | B7: ='Adani Enterprises'!H5 -> -0.19123597 | C7: ='Adani Enterprises'!H6 -> 0.067060416 | D7: =1/5 -> 0.2 | G7: HDFC Life Insurance | H7: 0.75538372 | I7: 0.32294721 | J7: 0.063422427 | K7: 1
A8: Hindalco Industries | B8: ='Hindalco Industries'!H4 -> 0.038293867 | C8: ='Hindalco Industries'!H5 -> 0.046919461 | D8: =1/5 -> 0.2 | G8: Adani Enterprises | H8: 0.65975558 | I8: 0.88425693 | J8: 0.79214576 | K8: 0.42782349 | L8: 1
G9: Hindalco Industries | H9: 0.57432852 | I9: 0.62597246 | J9: 0.35794412 | K9: 0.48507367 | L9: 0.5415577 | M9: 1
A10: Portfolio Returns | B10: =SUMPRODUCT(B4:B8,D4:D8) -> -0.098296953 | C10: =SUMPRODUCT(B2:B6,D2:D6)
B11: =(B4*D4)+(B5*D5)+(B6*D6)+(B7*D7)+(B8*D8) -> -0.098296953 | C11: =(B2*D2)+(B3*D3)+(B4*D4)+(B5*D5)+(B6*D6) | G11: Computed correlation from data analysis toolpak.
A13: Portfolio Risk/Variance (Formula Below) | B13: =SUM(I16:I20)+SUM(H23:H32) -> 0.0013048096 | C13: Portfolio Risk/ Variance (Formula Below) | D13: =B13*10000 -> 13.048096
A15: Portfolio Standard Deviation | B15: =SQRT(B13) -> 0.036122148 | C15: =SQRT(B13) | D15: =SQRT(D13) -> 3.6122148 | G15: Security Name | H15: Security Number | I15: Variance of Security | K15: Correlation Coefficient of Security
G16: NTPC | H16: 1 | I16: =(D4^2)*(C4^2) -> 6.0371286e-05 | K16: 1 & 2 | L16: =I6 -> 0.75328724
G17: Dabur India | H17: 2 | I17: =(D5^2)*(C5^2) -> 4.5916456e-05 | K17: 1 & 3 | L17: =I7 -> 0.32294721
G18: HDFC Life Insurance | H18: 3 | I18: =(D6^2)*(C6^2) -> 5.4511993e-05 | K18: 1 & 4 | L18: =I8 -> 0.88425693
G19: Adani Enterprises | H19: 4 | I19: =(D7^2)*(C7^2) -> 0.00017988397 | K19: 1 & 5 | L19: =I9 -> 0.62597246
G20: Hindalco Industries | H20: 5 | I20: =(D8^2)*(C8^2) -> 8.8057433e-05 | K20: 2 & 3 | L20: =J7 -> 0.063422427
K21: 2 & 4 | L21: =J8 -> 0.79214576
G22: Covariance No: | H22: Covariance | K22: 2 & 5 | L22: =J9 -> 0.35794412
G23: 1 & 2 | H23: =2*$D$4*D5*L16*$C$4*C5 -> 7.9321333e-05 | K23: 3 & 4 | L23: =K8 -> 0.42782349
G24: 1 & 3 | H24: =2*$D$4*D6*L17*$C$4*C6 -> 3.7052949e-05 | K24: 3 & 5 | L24: =K9 -> 0.48507367
G25: 1 & 4 | H25: =2*$D$4*D7*L18*$C$4*C7 -> 0.0001842977 | K25: 4 & 5 | L25: =L9 -> 0.5415577
G26: 1 & 5 | H26: =2*$D$4*D8*L19*$C$4*C8 -> 9.1281643e-05
G27: 2 & 3 | H27: =2*$D$5*D6*L20*$C$5*C6 -> 6.3460438e-06
G28: 2 & 4 | H28: =2*$D$5*D7*L21*$C$5*C7 -> 0.00014398443 | K28: 5 Seecurities
G29: 2 & 5 | H29: =2*$D$5*D8*L22*$C$5*C8 -> 4.5521065e-05 | K29: 5 Variances
A30: Portfolio Variance Formula | G30: 3 & 4 | H30: =2*$D$6*D7*L23*$C$6*C7 -> 8.4729939e-05 | K30: 10 Covariances
G31: 3 & 5 | H31: =2*$D$6*D8*L24*$C$6*C8 -> 6.7215083e-05
G32: 4 & 5 | H32: =2*D7*D8*L25*C7*C8 -> 0.00013631824

Sheet Single Index Model
A1: Single Index Model
A3: Security Name | B3: Expected Returns (Individual ) | C3: Standard Deviation (Individual) | D3: Weights | E3: Alpha - Intercept Function | F3: Beta - Slope Function | G3: Residual Variance - Regression | H3: Weight * Alpha | I3: Weight * Beta | J3: Weight ^2 | K3: Weight^2 * Residual Variance
A4: NTPC | B4: =NTPC!H4 -> -0.17481602 | C4: =NTPC!H5 -> 0.038849481 | D4: =1/5 -> 0.2 | E4: ='Alpha - Beta Computation'!J4 -> -0.0006940993 | F4: ='Alpha - Beta Computation'!J5 -> 1.1116739 | G4: =Regression!D13 -> 0.00014927598 | H4: =D4*E4 -> -0.00013881986 | I4: =D4*F4 -> 0.22233478 | J4: =D4^2 -> 0.04 | K4: =J4*G4 -> 5.971039e-06
A5: Dabur India | B5: ='Dabur India'!H4 -> -0.21424725 | C5: ='Dabur India'!H5 -> 0.033880841 | D5: =1/5 -> 0.2 | E5: ='Alpha - Beta Computation'!K4 -> -0.00085039631 | F5: ='Alpha - Beta Computation'!K5 -> 0.60298073 | G5: =Regression!N13 -> 0.00015520372 | H5: =D5*E5 -> -0.00017007926 | I5: =D5*F5 -> 0.12059615 | J5: =D5^2 -> 0.04 | K5: =J5*G5 -> 6.2081487e-06
A6: HDFC Life Insurance | B6: ='HDFC Life Insurance'!H4 -> 0.050520605 | C6: ='HDFC Life Insurance'!H5 -> 0.036916119 | D6: =1/5 -> 0.2 | E6: ='Alpha - Beta Computation'!L4 -> 0.00020020086 | F6: ='Alpha - Beta Computation'!L5 -> 0.80206706 | G6: =Regression!D33 -> 0.00016895457 | H6: =D6*E6 -> 4.0040172e-05 | I6: =D6*F6 -> 0.16041341 | J6: =D6^2 -> 0.04 | K6: =J6*G6 -> 6.7581829e-06
A7: Adani Enterprises | B7: ='Adani Enterprises'!H5 -> -0.19123597 | C7: ='Adani Enterprises'!H6 -> 0.067060416 | D7: =1/5 -> 0.2 | E7: ='Alpha - Beta Computation'!M4 -> -0.00075638371 | F7: ='Alpha - Beta Computation'!M5 -> 1.5777153 | G7: =Regression!N33 -> 0.00052819439 | H7: =D7*E7 -> -0.00015127674 | I7: =D7*F7 -> 0.31554306 | J7: =D7^2 -> 0.04 | K7: =J7*G7 -> 2.1127776e-05
A8: Hindalco Industries | B8: ='Hindalco Industries'!H4 -> 0.038293867 | C8: ='Hindalco Industries'!H5 -> 0.046919461 | D8: =1/5 -> 0.2 | E8: ='Alpha - Beta Computation'!N4 -> 0.00015150524 | F8: ='Alpha - Beta Computation'!N5 -> 1.3126941 | G8: =Regression!D54 -> 0.00022347404 | H8: =D8*E8 -> 3.0301048e-05 | I8: =D8*F8 -> 0.26253882 | J8: =D8^2 -> 0.04 | K8: =J8*G8 -> 8.9389614e-06
A10: NIFTY 50 (Market Return) | B10: ='NIFTY 50'!G4 -> 8.7260692e-05
A13: Portfolio Alpha (Formula on the right) | B13: =SUM(H4:H8) -> -0.00038983464 | C13: =SUM(H4:H8)
A14: Portfolio Beta (Formula on the right0 | B14: =SUM(I4:I8) -> 1.0814262 | C14: =SUM(I4:I8)
A17: Portfolio Return (Formula Shown Below) | B17: =B13+(B14*B10) -> -0.00029546864 | C17: =B13+(B14*B10)
E18: Portfolio Alpha Formula | H18: Portfolio Beta Formula
A19: Portfolio Risk (Formula Shown Below) | B19: =((B14^2)*(B10^2)+SUM(K4:K8)) -> 4.9013013e-05 | C19: =((B14^2)*(B10^2)+SUM(K4:K8))
A21: Portfolio Standard Deviation | B21: =SQRT(B19) -> 0.0070009294 | C21: =SQRT(B19
H28: Portfolio Return Formula
E29: Portfolio Risk Formula

Sheet Regression
A1: SUMMARY OUTPUT - NIFTY50 and NTPC | K1: SUMMARY OUTPUT - NIFTY50 and Dabur India
A3: Regression Statistics | K3: Regression Statistics
A4: Multiple R | B4: 0.61191041 | K4: Multiple R | L4: 0.38057906
A5: R Square | B5: 0.37443435 | K5: R Square | L5: 0.14484042
A6: Adjusted R Square | B6: 0.37191191 | K6: Adjusted R Square | L6: 0.1413922
A7: Standard Error | B7: 0.012217855 | K7: Standard Error | L7: 0.012458078
A8: Observations | B8: 250 | K8: Observations | L8: 250
A10: ANOVA | K10: ANOVA
B11: df | C11: SS | D11: MS | E11: F | F11: Significance F | L11: df | M11: SS | N11: MS | O11: F | P11: Significance F
A12: Regression | B12: 1 | C12: 0.022158705 | D12: 0.022158705 | E12: 148.4412 | F12: 4.4933653e-27 | K12: Regression | L12: 1 | M12: 0.0065192318 | N12: 0.0065192318 | O12: 42.004353 | P12: 4.8748788e-10
A13: Residual | B13: 248 | C13: 0.037020442 | D13: 0.00014927598 | K13: Residual | L13: 248 | M13: 0.038490522 | N13: 0.00015520372
A14: Total | B14: 249 | C14: 0.059179147 | K14: Total | L14: 249 | M14: 0.045009754
B16: Coefficients | C16: Standard Error | D16: t Stat | E16: P-value | F16: Lower 95% | G16: Upper 95% | H16: Lower 95.0% | I16: Upper 95.0% | L16: Coefficients | M16: Standard Error | N16: t Stat | O16: P-value | P16: Lower 95% | Q16: Upper 95% | R16: Lower 95.0% | S16: Upper 95.0%
A17: Intercept | B17: -0.0006940993 | C17: 0.00077272498 | D17: -0.89824882 | E17: 0.36992415 | F17: -0.0022160396 | G17: 0.00082784101 | H17: -0.0022160396 | I17: 0.00082784101 | K17: Intercept | L17: -0.00085039631 | M17: 0.00078791806 | N17: -1.0792954 | O17: 0.28150464 | P17: -0.0024022605 | Q17: 0.00070146792 | R17: -0.0024022605 | S17: 0.00070146792
A18: NIFTY50 | B18: 1.1116739 | C18: 0.091243132 | D18: 12.183645 | E18: 4.4933653e-27 | F18: 0.93196367 | G18: 1.2913842 | H18: 0.93196367 | I18: 1.2913842 | K18: NIFTY50 | L18: 0.60298073 | M18: 0.093037126 | N18: 6.4810765 | O18: 4.8748788e-10 | P18: 0.41973708 | Q18: 0.78622439 | R18: 0.41973708 | S18: 0.78622439
A21: SUMMARY OUTPUT - NIFTY50 and HDFC Life Insurance | K21: SUMMARY OUTPUT - NIFTY50 and Adani Enterprises
A23: Regression Statistics | K23: Regression Statistics
A24: Multiple R | B24: 0.46461186 | K24: Multiple R | L24: 0.50411678
A25: R Square | B25: 0.21586418 | K25: R Square | L25: 0.25413373
A26: Adjusted R Square | B26: 0.21270234 | K26: Adjusted R Square | L26: 0.25112621
A27: Standard Error | B27: 0.012998253 | K27: Standard Error | L27: 0.02298248
A28: Observations | B28: 250 | K28: Observations | L28: 250
A30: ANOVA | K30: ANOVA
B31: df | C31: SS | D31: MS | E31: F | F31: Significance F | L31: df | M31: SS | N31: MS | O31: F | P31: Significance F
A32: Regression | B32: 1 | C32: 0.011534822 | D32: 0.011534822 | E32: 68.271739 | F32: 8.6220147e-15 | K32: Regression | L32: 1 | M32: 0.044632048 | N32: 0.044632048 | O32: 84.499284 | P32: 1.6097075e-17
A33: Residual | B33: 248 | C33: 0.041900734 | D33: 0.00016895457 | K33: Residual | L33: 248 | M33: 0.13099221 | N33: 0.00052819439
A34: Total | B34: 249 | C34: 0.053435556 | K34: Total | L34: 249 | M34: 0.17562426
B36: Coefficients | C36: Standard Error | D36: t Stat | E36: P-value | F36: Lower 95% | G36: Upper 95% | H36: Lower 95.0% | I36: Upper 95.0% | L36: Coefficients | M36: Standard Error | N36: t Stat | O36: P-value | P36: Lower 95% | Q36: Upper 95% | R36: Lower 95.0% | S36: Upper 95.0%
A37: Intercept | B37: 0.00020020086 | C37: 0.00082208168 | D37: 0.24352916 | E37: 0.80779682 | F37: -0.0014189512 | G37: 0.0018193529 | H37: -0.0014189512 | I37: 0.0018193529 | K37: Intercept | L37: -0.00075638371 | M37: 0.0014535397 | N37: -0.52037363 | O37: 0.60326743 | P37: -0.0036192401 | Q37: 0.0021064726 | R37: -0.0036192401 | S37: 0.0021064726
A38: NIFTY50 | B38: 0.80206706 | C38: 0.097071156 | D38: 8.2626714 | E38: 8.6220147e-15 | F38: 0.61087808 | G38: 0.99325605 | H38: 0.61087808 | I38: 0.99325605 | K38: NIFTY50 | L38: 1.5777153 | M38: 0.17163352 | N38: 9.1923492 | O38: 1.6097075e-17 | P38: 1.2396701 | Q38: 1.9157605 | R38: 1.2396701 | S38: 1.9157605
A42: SUMMARY OUTPUT - NIFTY50 and Hindalco Industries
A44: Regression Statistics
A45: Multiple R | B45: 0.5982823
A46: R Square | B46: 0.35794171
A47: Adjusted R Square | B47: 0.35535277
A48: Standard Error | B48: 0.014949048
A49: Observations | B49: 250
A51: ANOVA
B52: df | C52: SS | D52: MS | E52: F | F52: Significance F
A53: Regression | B53: 1 | C53: 0.030897021 | D53: 0.030897021 | E53: 138.25777 | F53: 1.1575516e-25
...

Sheet NTPC
A1: Date | B1: series | C1: close | D1: Daily Returns (Ln(P1/PO)) | E1: Annualized Returns
A2: 45499 | B2: EQ | C2: 396.3 | D2: 0 | E2: =D2*252 -> 0
A3: 45502 | B3: EQ | C3: 393.9 | D3: =LN(C3/C2) -> -0.0060744302 | E3: =D3*252 -> -1.5307564 | G3: NTPC Limited
A4: 45503 | B4: EQ | C4: 406.95 | D4: =LN(C4/C3) -> 0.032593258 | E4: =D4*252 -> 8.213501 | G4: Expected (Returns) | H4: =AVERAGE(E2:E251) -> -0.17481602 | J4: =AVERAGE(E2:E251)
A5: 45504 | B5: EQ | C5: 416 | D5: =LN(C5/C4) -> 0.021994932 | E5: =D5*252 -> 5.542723 | G5: Risk (Standard Deviation) | H5: =_xlfn.STDEV.S(E2:E251)/100 -> 0.038849481 | J5: =STDEV.S(E2:E251)
A6: 45505 | B6: EQ | C6: 423.45 | D6: =LN(C6/C5) -> 0.017750183 | E6: =D6*252 -> 4.4730461
A7: 45506 | B7: EQ | C7: 419.7 | D7: =LN(C7/C6) -> -0.008895273 | E7: =D7*252 -> -2.2416088
A8: 45509 | B8: EQ | C8: 413.25 | D8: =LN(C8/C7) -> -0.015487434 | E8: =D8*252 -> -3.9028333 | G8: Daily Returns = Ln(P1/P0)
A9: 45510 | B9: EQ | C9: 415 | D9: =LN(C9/C8) -> 0.0042257835 | E9: =D9*252 -> 1.0648974 | G9: Single Annualized Return = Daily Return * 252
A10: 45511 | B10: EQ | C10: 416.3 | D10: =LN(C10/C9) -> 0.003127634 | E10: =D10*252 -> 0.78816376
A11: 45512 | B11: EQ | C11: 407.7 | D11: =LN(C11/C10) -> -0.020874544 | E11: =D11*252 -> -5.2603852 | G11: 252 trading days
A12: 45513 | B12: EQ | C12: 410.65 | D12: =LN(C12/C11) -> 0.0072096604 | E12: =D12*252 -> 1.8168344
A13: 45516 | B13: EQ | C13: 400.85 | D13: =LN(C13/C12) -> -0.024153978 | E13: =D13*252 -> -6.0868024
A14: 45517 | B14: EQ | C14: 396.2 | D14: =LN(C14/C13) -> -0.011668158 | E14: =D14*252 -> -2.9403759
A15: 45518 | B15: EQ | C15: 396.35 | D15: =LN(C15/C14) -> 0.00037852502 | E15: =D15*252 -> 0.095388305
A16: 45520 | B16: EQ | C16: 398.05 | D16: =LN(C16/C15) -> 0.0042799663 | E16: =D16*252 -> 1.0785515
A17: 45523 | B17: EQ | C17: 403.1 | D17: =LN(C17/C16) -> 0.012607045 | E17: =D17*252 -> 3.1769752
A18: 45524 | B18: EQ | C18: 406.25 | D18: =LN(C18/C17) -> 0.0077840635 | E18: =D18*252 -> 1.961584
A19: 45525 | B19: EQ | C19: 408.95 | D19: =LN(C19/C18) -> 0.0066241655 | E19: =D19*252 -> 1.6692897
A20: 45526 | B20: EQ | C20: 403.35 | D20: =LN(C20/C19) -> -0.013788228 | E20: =D20*252 -> -3.4746334
A21: 45527 | B21: EQ | C21: 401.95 | D21: =LN(C21/C20) -> -0.0034769686 | E21: =D21*252 -> -0.87619609
A22: 45530 | B22: EQ | C22: 414.85 | D22: =LN(C22/C21) -> 0.031589306 | E22: =D22*252 -> 7.9605052
A23: 45531 | B23: EQ | C23: 409.65 | D23: =LN(C23/C22) -> -0.012613873 | E23: =D23*252 -> -3.1786959
... A251: 45863 | B251: EQ | C251: 333.2 | D251: =LN(C251/C250) -> -0.016962168 | E251: =D251*252 -> -4.2744664

Sheet Dabur India
A1: Date | B1: series | C1: close | D1: Daily Returns (Ln(P1/PO)) | E1: Annualized Returns
A2: 45499 | B2: EQ | C2: 632.45 | D2: 0 | E2: =D2*252 -> 0
A3: 45502 | B3: EQ | C3: 641.1 | D3: =LN(C3/C2) -> 0.013584285 | E3: =D3*252 -> 3.4232398 | G3: Dabur India Limited
A4: 45503 | B4: EQ | C4: 633.9 | D4: =LN(C4/C3) -> -0.011294238 | E4: =D4*252 -> -2.8461479 | G4: Expected (Returns) | H4: =AVERAGE(E2:E251) -> -0.21424725 | J4: =AVERAGE(E2:E251)
A5: 45504 | B5: EQ | C5: 635.7 | D5: =LN(C5/C4) -> 0.0028355407 | E5: =D5*252 -> 0.71455624 | G5: Risk (Standard Deviation) | H5: =_xlfn.STDEV.S(E2:E251)/100 -> 0.033880841 | J5: =STDEV.S(E2:E251)
A6: 45505 | B6: EQ | C6: 643.5 | D6: =LN(C6/C5) -> 0.012195273 | E6: =D6*252 -> 3.0732088
A7: 45506 | B7: EQ | C7: 627.55 | D7: =LN(C7/C6) -> -0.025098678 | E7: =D7*252 -> -6.3248668
A8: 45509 | B8: EQ | C8: 634 | D8: =LN(C8/C7) -> 0.010225605 | E8: =D8*252 -> 2.5768525 | G8: Daily Returns = Ln(P1/P0)
A9: 45510 | B9: EQ | C9: 629.15 | D9: =LN(C9/C8) -> -0.0076792524 | E9: =D9*252 -> -1.9351716 | G9: Single Annualized Return = Daily Return * 252
A10: 45511 | B10: EQ | C10: 639.25 | D10: =LN(C10/C9) -> 0.015925912 | E10: =D10*252 -> 4.0133299
A11: 45512 | B11: EQ | C11: 637.45 | D11: =LN(C11/C10) -> -0.0028197716 | E11: =D11*252 -> -0.71058244 | G11: 252 trading days
A12: 45513 | B12: EQ | C12: 623.95 | D12: =LN(C12/C11) -> -0.021405606 | E12: =D12*252 -> -5.3942126
A13: 45516 | B13: EQ | C13: 620.35 | D13: =LN(C13/C12) -> -0.0057864021 | E13: =D13*252 -> -1.4581733
A14: 45517 | B14: EQ | C14: 605.85 | D14: =LN(C14/C13) -> -0.023651404 | E14: =D14*252 -> -5.9601539
A15: 45518 | B15: EQ | C15: 604.4 | D15: =LN(C15/C14) -> -0.0023962003 | E15: =D15*252 -> -0.60384247
A16: 45520 | B16: EQ | C16: 617.6 | D16: =LN(C16/C15) -> 0.021604768 | E16: =D16*252 -> 5.4444016
A17: 45523 | B17: EQ | C17: 621.3 | D17: =LN(C17/C16) -> 0.0059730584 | E17: =D17*252 -> 1.5052107
A18: 45524 | B18: EQ | C18: 623.1 | D18: =LN(C18/C17) -> 0.0028929625 | E18: =D18*252 -> 0.72902655
A19: 45525 | B19: EQ | C19: 634.35 | D19: =LN(C19/C18) -> 0.017893833 | E19: =D19*252 -> 4.5092459
A20: 45526 | B20: EQ | C20: 646.15 | D20: =LN(C20/C19) -> 0.018430822 | E20: =D20*252 -> 4.6445672
A21: 45527 | B21: EQ | C21: 643.25 | D21: =LN(C21/C20) -> -0.0044982238 | E21: =D21*252 -> -1.1335524
A22: 45530 | B22: EQ | C22: 654.55 | D22: =LN(C22/C21) -> 0.017414525 | E22: =D22*252 -> 4.3884604
A23: 45531 | B23: EQ | C23: 643.4 | D23: =LN(C23/C22) -> -0.017181362 | E23: =D23*252 -> -4.3297032
... A251: 45863 | B251: EQ | C251: 511.35 | D251: =LN(C251/C250) -> -0.00234398 | E251: =D251*252 -> -0.59068295

Sheet HDFC Life Insurance
A1: Date | B1: series | C1: close | D1: Daily Returns (Ln(P1/PO)) | E1: Annualized Returns
A2: 45499 | B2: EQ | C2: 703.35 | D2: 0 | E2: =D2*252 -> 0
A3: 45502 | B3: EQ | C3: 696.85 | D3: =LN(C3/C2) -> -0.0092844546 | E3: =D3*252 -> -2.3396826 | G3: HDFC Life Insurance
A4: 45503 | B4: EQ | C4: 697.2 | D4: =LN(C4/C3) -> 0.00050213408 | E4: =D4*252 -> 0.12653779 | G4: Expected (Returns) | H4: =AVERAGE(E2:E251) -> 0.050520605 | J4: =AVERAGE(E2:E251)
A5: 45504 | B5: EQ | C5: 715.5 | D5: =LN(C5/C4) -> 0.025909285 | E5: =D5*252 -> 6.5291399 | G5: Risk (Standard Deviation) | H5: =_xlfn.STDEV.S(E2:E251)/100 -> 0.036916119 | J5: =STDEV.S(E2:E251)
A6: 45505 | B6: EQ | C6: 713.6 | D6: =LN(C6/C5) -> -0.0026590177 | E6: =D6*252 -> -0.67007247
A7: 45506 | B7: EQ | C7: 707.4 | D7: =LN(C7/C6) -> -0.0087263045 | E7: =D7*252 -> -2.1990287
A8: 45509 | B8: EQ | C8: 710.9 | D8: =LN(C8/C7) -> 0.0049354962 | E8: =D8*252 -> 1.243745
A9: 45510 | B9: EQ | C9: 679.6 | D9: =LN(C9/C8) -> -0.045027383 | E9: =D9*252 -> -11.346901 | G9: Daily Returns = Ln(P1/P0)
A10: 45511 | B10: EQ | C10: 696.25 | D10: =LN(C10/C9) -> 0.024204401 | E10: =D10*252 -> 6.0995092 | G10: Single Annualized Return = Daily Return * 252
A11: 45512 | B11: EQ | C11: 710.35 | D11: =LN(C11/C10) -> 0.020049015 | E11: =D11*252 -> 5.0523518
A12: 45513 | B12: EQ | C12: 702.4 | D12: =LN(C12/C11) -> -0.011254764 | E12: =D12*252 -> -2.8362005 | G12: 252 trading days
A13: 45516 | B13: EQ | C13: 702.45 | D13: =LN(C13/C12) -> 7.1181977e-05 | E13: =D13*252 -> 0.017937858
A14: 45517 | B14: EQ | C14: 685 | D14: =LN(C14/C13) -> -0.025155386 | E14: =D14*252 -> -6.3391573
A15: 45518 | B15: EQ | C15: 686.35 | D15: =LN(C15/C14) -> 0.0019688634 | E15: =D15*252 -> 0.49615359
A16: 45520 | B16: EQ | C16: 689.4 | D16: =LN(C16/C15) -> 0.0044339524 | E16: =D16*252 -> 1.117356
A17: 45523 | B17: EQ | C17: 685.7 | D17: =LN(C17/C16) -> -0.0053814398 | E17: =D17*252 -> -1.3561228
A18: 45524 | B18: EQ | C18: 710.6 | D18: =LN(C18/C17) -> 0.035669469 | E18: =D18*252 -> 8.9887063
A19: 45525 | B19: EQ | C19: 724.55 | D19: =LN(C19/C18) -> 0.019441089 | E19: =D19*252 -> 4.8991544
A20: 45526 | B20: EQ | C20: 726 | D20: =LN(C20/C19) -> 0.0019992423 | E20: =D20*252 -> 0.50380907
A21: 45527 | B21: EQ | C21: 729 | D21: =LN(C21/C20) -> 0.0041237172 | E21: =D21*252 -> 1.0391767
A22: 45530 | B22: EQ | C22: 725.65 | D22: =LN(C22/C21) -> -0.0046059271 | E22: =D22*252 -> -1.1606936
A23: 45531 | B23: EQ | C23: 739.55 | D23: =LN(C23/C22) -> 0.018974088 | E23: =D23*252 -> 4.7814702
A24: 45532 | B24: EQ | C24: 742.1 | D24: =LN(C24/C23) -> 0.0034421119 | E24: =D24*252 -> 0.86741219
... A250: 45863 | B250: EQ | C250: 762.35 | D250: =LN(C250/C249) -> 0.0066462917 | E250: =D250*252 -> 1.6748655
B251: EQ | C251: 739.5 | D251: =LN(C251/C250) -> -0.030431486 | E251: =D251*252 -> -7.6687344

Sheet Adani Enterprises
A1: Date | B1: series | C1: close | D1: Daily Returns (Ln(P1/PO)) | E1: Annualized Returns
A2: 45499 | B2: EQ | C2: 3080.5 | D2: 0 | E2: =D2*252 -> 0
A3: 45502 | B3: EQ | C3: 3089.35 | D3: =LN(C3/C2) -> 0.0028687913 | E3: =D3*252 -> 0.72293541
A4: 45503 | B4: EQ | C4: 3128.75 | D4: =LN(C4/C3) -> 0.012672851 | E4: =D4*252 -> 3.1935584 | G4: Adani Enterprises
A5: 45504 | B5: EQ | C5: 3169.4 | D5: =LN(C5/C4) -> 0.012908732 | E5: =D5*252 -> 3.2530004 | G5: Expected (Returns) | H5: =AVERAGE(E3:E252) -> -0.19123597 | J5: =AVERAGE(E2:E251)
A6: 45505 | B6: EQ | C6: 3217.25 | D6: =LN(C6/C5) -> 0.014984662 | E6: =D6*252 -> 3.7761348 | G6: Risk (Standard Deviation) | H6: =_xlfn.STDEV.S(E3:E252)/100 -> 0.067060416 | J6: =STDEV.S(E2:E251)
A7: 45506 | B7: EQ | C7: 3160.9 | D7: =LN(C7/C6) -> -0.01767016 | E7: =D7*252 -> -4.4528804
A8: 45509 | B8: EQ | C8: 3038.2 | D8: =LN(C8/C7) -> -0.039591562 | E8: =D8*252 -> -9.9770737
A9: 45510 | B9: EQ | C9: 3072.7 | D9: =LN(C9/C8) -> 0.011291419 | E9: =D9*252 -> 2.8454376 | G9: Daily Returns = Ln(P1/P0)
A10: 45511 | B10: EQ | C10: 3185.95 | D10: =LN(C10/C9) -> 0.036193864 | E10: =D10*252 -> 9.1208537 | G10: Single Annualized Return = Daily Return * 252
A11: 45512 | B11: EQ | C11: 3167.55 | D11: =LN(C11/C10) -> -0.0057920993 | E11: =D11*252 -> -1.459609
A12: 45513 | B12: EQ | C12: 3187.55 | D12: =LN(C12/C11) -> 0.0062941782 | E12: =D12*252 -> 1.5861329 | G12: 252 trading days
A13: 45516 | B13: EQ | C13: 3151.75 | D13: =LN(C13/C12) -> -0.011294743 | E13: =D13*252 -> -2.8462751
A14: 45517 | B14: EQ | C14: 3092.2 | D14: =LN(C14/C13) -> -0.019075042 | E14: =D14*252 -> -4.8069107
A15: 45518 | B15: EQ | C15: 3040.1 | D15: =LN(C15/C14) -> -0.016992402 | E15: =D15*252 -> -4.2820853
A16: 45520 | B16: EQ | C16: 3108.8 | D16: =LN(C16/C15) -> 0.02234639 | E16: =D16*252 -> 5.6312903
A17: 45523 | B17: EQ | C17: 3102.55 | D17: =LN(C17/C16) -> -0.0020124456 | E17: =D17*252 -> -0.5071363
A18: 45524 | B18: EQ | C18: 3070.65 | D18: =LN(C18/C17) -> -0.010335088 | E18: =D18*252 -> -2.6044423
A19: 45525 | B19: EQ | C19: 3115.7 | D19: =LN(C19/C18) -> 0.014564581 | E19: =D19*252 -> 3.6702743
A20: 45526 | B20: EQ | C20: 3099.05 | D20: =LN(C20/C19) -> -0.0053582332 | E20: =D20*252 -> -1.3502748
A21: 45527 | B21: EQ | C21: 3076.35 | D21: =LN(C21/C20) -> -0.0073517836 | E21: =D21*252 -> -1.8526495
A22: 45530 | B22: EQ | C22: 3069 | D22: =LN(C22/C21) -> -0.0023920537 | E22: =D22*252 -> -0.60279752
A23: 45531 | B23: EQ | C23: 3067.1 | D23: =LN(C23/C22) -> -0.00061928589 | E23: =D23*252 -> -0.15606004
A24: 45532 | B24: EQ | C24: 3028 | D24: =LN(C24/C23) -> -0.012830154 | E24: =D24*252 -> -3.2331989
... A251: 45863 | B251: EQ | C251: 2550.1 | D251: =LN(C251/C250) -> -0.022604432 | E251: =D251*252 -> -5.696317

Sheet Hindalco Industries
A1: Date | B1: series | C1: close | D1: Daily Returns (Ln(P1/PO)) | E1: Annualized Returns
A2: 45499 | B2: EQ | C2: 667.6 | D2: 0 | E2: =D2*252 -> 0
A3: 45502 | B3: EQ | C3: 666.85 | D3: =LN(C3/C2) -> -0.0011240587 | E3: =D3*252 -> -0.2832628 | G3: Adani Enterprises
A4: 45503 | B4: EQ | C4: 660.5 | D4: =LN(C4/C3) -> -0.0095680091 | E4: =D4*252 -> -2.4111383 | G4: Expected (Returns) | H4: =AVERAGE(E2:E251) -> 0.038293867 | J4: =AVERAGE(E2:E251)
A5: 45504 | B5: EQ | C5: 669.6 | D5: =LN(C5/C4) -> 0.013683395 | E5: =D5*252 -> 3.4482156 | G5: Risk (Standard Deviation) | H5: =_xlfn.STDEV.S(E2:E251)/100 -> 0.046919461 | J5: =STDEV.S(E2:E251)
A6: 45505 | B6: EQ | C6: 673.5 | D6: =LN(C6/C5) -> 0.0058074767 | E6: =D6*252 -> 1.4634841
A7: 45506 | B7: EQ | C7: 648.05 | D7: =LN(C7/C6) -> -0.038520142 | E7: =D7*252 -> -9.7070758
A8: 45509 | B8: EQ | C8: 614.3 | D8: =LN(C8/C7) -> -0.053484446 | E8: =D8*252 -> -13.47808
A9: 45510 | B9: EQ | C9: 610.3 | D9: =LN(C9/C8) -> -0.0065327686 | E9: =D9*252 -> -1.6462577 | G9: Daily Returns = Ln(P1/P0)
A10: 45511 | B10: EQ | C10: 623.7 | D10: =LN(C10/C9) -> 0.021718844 | E10: =D10*252 -> 5.4731487 | G10: Single Annualized Return = Daily Return * 252
A11: 45512 | B11: EQ | C11: 614.05 | D11: =LN(C11/C10) -> -0.015593125 | E11: =D11*252 -> -3.9294676
A12: 45513 | B12: EQ | C12: 622.9 | D12: =LN(C12/C11) -> 0.014309634 | E12: =D12*252 -> 3.6060278 | G12: 252 trading days
A13: 45516 | B13: EQ | C13: 629.35 | D13: =LN(C13/C12) -> 0.010301548 | E13: =D13*252 -> 2.5959902
A14: 45517 | B14: EQ | C14: 621.4 | D14: =LN(C14/C13) -> -0.012712544 | E14: =D14*252 -> -3.203561
A15: 45518 | B15: EQ | C15: 621.45 | D15: =LN(C15/C14) -> 8.0460233e-05 | E15: =D15*252 -> 0.020275979
A16: 45520 | B16: EQ | C16: 634.15 | D16: =LN(C16/C15) -> 0.020230062 | E16: =D16*252 -> 5.0979757
A17: 45523 | B17: EQ | C17: 658.85 | D17: =LN(C17/C16) -> 0.038210371 | E17: =D17*252 -> 9.6290136
A18: 45524 | B18: EQ | C18: 672.9 | D18: =LN(C18/C17) -> 0.021100839 | E18: =D18*252 -> 5.3174115
A19: 45525 | B19: EQ | C19: 685.6 | D19: =LN(C19/C18) -> 0.018697637 | E19: =D19*252 -> 4.7118045
A20: 45526 | B20: EQ | C20: 685.55 | D20: =LN(C20/C19) -> -7.2931481e-05 | E20: =D20*252 -> -0.018378733
A21: 45527 | B21: EQ | C21: 685.1 | D21: =LN(C21/C20) -> -0.00065662279 | E21: =D21*252 -> -0.16546894
A22: 45530 | B22: EQ | C22: 711.85 | D22: =LN(C22/C21) -> 0.038302402 | E22: =D22*252 -> 9.6522053
A23: 45531 | B23: EQ | C23: 703.5 | D23: =LN(C23/C22) -> -0.011799339 | E23: =D23*252 -> -2.9734333
A24: 45532 | B24: EQ | C24: 705.05 | D24: =LN(C24/C23) -> 0.0022008457 | E24: =D24*252 -> 0.55461312
... A251: 45863 | B251: EQ | C251: 693.45 | D251: =LN(C251/C250) -> -0.0030956434 | E251: =D251*252 -> -0.78010213

Sheet NIFTY 50
A1: Date | B1: Close | C1: Daily Returns (Ln(P1/PO)) | D1: Annualized Returns
A2: 45499 | B2: 24834.85 | C2: 0 | D2: =C2*252 -> 0
A3: 45502 | B3: 24836.1 | C3: =LN(B3/B2) -> 5.033123e-05 | D3: =C3*252 -> 0.01268347 | F3: Adani Enterprises
A4: 45503 | B4: 24857.3 | C4: =LN(B4/B3) -> 0.00085323207 | D4: =C4*252 -> 0.21501448 | F4: Expected (Returns) | G4: =AVERAGE(D2:D251) -> 8.7260692e-05 | I4: =AVERAGE(D2:D251)
A5: 45504 | B5: 24951.15 | C5: =LN(B5/B4) -> 0.0037684413 | D5: =C5*252 -> 0.94964722 | F5: Risk (Standard Deviation) | G5: =_xlfn.STDEV.S(D2:D251)/100 -> 0.02138433 | I5: =STDEV.S(D2:D251)
A6: 45505 | B6: 25010.9 | C6: =LN(B6/B5) -> 0.0023918165 | D6: =C6*252 -> 0.60273777
A7: 45506 | B7: 24717.7 | C7: =LN(B7/B6) -> -0.011792144 | D7: =C7*252 -> -2.9716202
A8: 45509 | B8: 24055.6 | C8: =LN(B8/B7) -> -0.027151769 | D8: =C8*252 -> -6.8422457
A9: 45510 | B9: 23992.55 | C9: =LN(B9/B8) -> -0.0026244522 | D9: =C9*252 -> -0.66136195 | F9: Daily Returns = Ln(P1/P0)
A10: 45511 | B10: 24297.5 | C10: =LN(B10/B9) -> 0.012630099 | D10: =C10*252 -> 3.1827849 | F10: Single Annualized Return = Daily Return * 252
A11: 45512 | B11: 24117 | C11: =LN(B11/B10) -> -0.0074564784 | D11: =C11*252 -> -1.8790326
A12: 45513 | B12: 24367.5 | C12: =LN(B12/B11) -> 0.010333291 | D12: =C12*252 -> 2.6039894 | F12: 252 trading days
A13: 45516 | B13: 24347 | C13: =LN(B13/B12) -> -0.00084163858 | D13: =C13*252 -> -0.21209292
A14: 45517 | B14: 24139 | C14: =LN(B14/B13) -> -0.0085798489 | D14: =C14*252 -> -2.1621219
A15: 45518 | B15: 24143.75 | C15: =LN(B15/B14) -> 0.00019675764 | D15: =C15*252 -> 0.049582926
A16: 45520 | B16: 24541.15 | C16: =LN(B16/B15) -> 0.016325753 | D16: =C16*252 -> 4.1140898
A17: 45523 | B17: 24572.65 | C17: =LN(B17/B16) -> 0.0012827354 | D17: =C17*252 -> 0.32324931
A18: 45524 | B18: 24698.85 | C18: =LN(B18/B17) -> 0.005122648 | D18: =C18*252 -> 1.2909073
A19: 45525 | B19: 24770.2 | C19: =LN(B19/B18) -> 0.0028846339 | D19: =C19*252 -> 0.72692774
A20: 45526 | B20: 24811.5 | C20: =LN(B20/B19) -> 0.0016659376 | D20: =C20*252 -> 0.41981628
A21: 45527 | B21: 24823.15 | C21: =LN(B21/B20) -> 0.00046943013 | D21: =C21*252 -> 0.11829639
A22: 45530 | B22: 25010.6 | C22: =LN(B22/B21) -> 0.0075230495 | D22: =C22*252 -> 1.8958085
A23: 45531 | B23: 25017.75 | C23: =LN(B23/B22) -> 0.00028583793 | D23: =C23*252 -> 0.072031159
A24: 45532 | B24: 25052.35 | C24: =LN(B24/B23) -> 0.0013820626 | D24: =C24*252 -> 0.34827977
... A251: 45863 | B251: 24837 | C251: =LN(B251/B250) -> -0.009022268 | D251: =C251*252 -> -2.2736115
