Workbook

Sheet ASSIGNMENT DETAILS
A1: Subject: | B1: Sustainable Finance and Responsible Investment
A2: Topic: | B2: CLSA Case Study Assignment
A3: Done by: | B3: Abhimanyu Babbar

Sheet 1. INPUTS
A1: 1. INPUTS
A2: Input Name | B2: Value | C2: Notes | D2: Source Link | E2: Source Tab
A3: Capital Market Inputs
A4: Risk-Free Rate | B4: 0.06607 | C4: India 10-Year Government Bond Yield obtained from Trading Economics as on 02/01/2026. | D4: https://tradingeconomics.com/india/government-bond-yield | E4: Figure 1
A5: Market Return | B5: ='1A. MARKET RETURNS CALCULATION'!C16 -> 0.15051788 | C5: As per NSE NIFTY 50 returns, 10 year average - Refer to sheet 1A. | D5: 1A. MARKET RETURNS CALCULATION | E5: 1A. MARKET RETURNS CALCULATION
A6: Market Risk Premium | B6: =B5-B4 -> 0.084447875 | C6: As per the CAPM formula component; Market Return - Risk-Free Rate. | D6: NA | E6: NA
A7: Beta (Levered) | B7: 0.83 | C7: As per MoneyControl. | D7: https://www.moneycontrol.com/india/stockpricequote/cement-major/dalmiabharat/OCL | E7: Figure 2
A8: Cost of Equity | B8: =B4+(B7*B6) -> 0.13616174 | C8: Calculated using CAPM; Ke = Rf + B(Rm-Rf) | D8: NA | E8: NA
A9: Debt & Tax Inputs
A10: Cost of Debt (Pre-Tax) | B10: =-'2. RAW FINANCIALS (CASE)'!E16/'2. RAW FINANCIALS (CASE)'!E70 -> 0.060727497 | C10: From Raw Financials using Interest Expenses/Total Debt. | D10: 2. RAW FINANCIALS (CASE) | E10: Figure 3
A11: Tax Rate | B11: 0.25 | C11: Current Corporate Tax Rate | D11: https://incometaxindia.gov.in/Documents/Left%20Menu/TAX%20RATES-domestic.htm
A12: Cost of Debt (After Tax) | B12: =B10*(1-B11) -> 0.045545623 | C12: Tax is reduced; Kd*(1-Tax Rate) | D12: NA | E12: NA
A13: Capital Structure
A14: Equity Weight | B14: ='2. RAW FINANCIALS (CASE)'!E68/('2. RAW FINANCIALS (CASE)'!E68+'2. RAW FINANCIALS (CASE)'!E70) -> 0.82929011 | C14: Obtained from Raw Financials using Total Equity / (Debt + Equity) | D14: 2. RAW FINANCIALS (CASE) | E14: 2. RAW FINANCIALS (CASE)'!A1
A15: Debt Weight | B15: =1-B14 -> 0.17070989 | C15: Obtained using 1 - Equity Weight | D15: NA | E15: NA
A16: WACC
A17: WACC | B17: =(B8*B14)+(B12*B15) -> 0.12069267 | C17: Weighted Average Cost of Capital; (Ke × Equity weight) + (Kd(after tax) × Debt weight) | D17: NA | E17: NA
A18: Terminal & Valuation Inputs
A19: Terminal Growth Rate | B19: 0.065 | C19: Obtained from World Bank Data as on 2024. | D19: https://data.worldbank.org/indicator/NY.GDP.MKTP.KD.ZG?locations=IN | E19: Figure 4
A20: Shares Outstanding | B20: =187565161/100000 -> 1875.6516 | C20: Obtained from Dalmia Cements Annual Report 2024-25. | D20: https://www.dalmiacement.com/assets/pdf/annual-reports/Dalmia-Bharat-IR-FY-24-25.pdf | E20: Figure 5
A21: ESG Scenarios FCFF Reduction
A22: Mild | B22: 0.05 | C22: As per the assignment guidelines. | D22: NA | E22: NA
A23: Moderate | B23: 0.15 | C23: As per the assignment guidelines. | D23: NA | E23: NA
A24: Severe | B24: 0.25 | C24: As per the assignment guidelines. | D24: NA | E24: NA
A25: Modelling Constraints
A26: Capex Growth Rate | B26: 0.01 | C26: As per the assignment guidelines. | D26: NA | E26: NA
A27: WC Change Growth Rate | B27: 0.02 | C27: As per the assignment guidelines. | D27: NA
A28: Depreciation Method | B28: Average of last 4 years depreciation. | C28: No PPE Schedule. | D28: NA
A29: Forecast Horizon (Years) | B29: 25 | C29: As per the assignment guidelines. | D29: NA

Sheet 1A. MARKET RETURNS CALCULATION
A1: 1A. NIFTY 50 MARKET RETURNS CALCULATION
A2: Date | B2: NIFTY 50 Closing Price | C2: NIFTY50 Annual Returns (P1-P0/P0) | D2: Source
A3: 40998 | B3: 5295.55 | C3: - | D3: https://www.nseindia.com/reports-indices-historical-index-data
A4: 41361 | B4: 5682.55 | C4: =(B4-B3)/B3 -> 0.073080228 | D4: https://www.nseindia.com/reports-indices-historical-index-data
A5: 41729 | B5: 6704.2 | C5: =(B5-B4)/B4 -> 0.17978724 | D5: https://www.nseindia.com/reports-indices-historical-index-data
A6: 42094 | B6: 8491 | C6: =(B6-B5)/B5 -> 0.2665195 | D6: https://www.nseindia.com/reports-indices-historical-index-data
A7: 42460 | B7: 7738.4 | C7: =(B7-B6)/B6 -> -0.088635025 | D7: https://www.nseindia.com/reports-indices-historical-index-data
A8: 42825 | B8: 9173.75 | C8: =(B8-B7)/B7 -> 0.18548408 | D8: https://www.nseindia.com/reports-indices-historical-index-data
A9: 43187 | B9: 10113.7 | C9: =(B9-B8)/B8 -> 0.10246083 | D9: https://www.nseindia.com/reports-indices-historical-index-data
A10: 43553 | B10: 11623.9 | C10: =(B10-B9)/B9 -> 0.14932221 | D10: https://www.nseindia.com/reports-indices-historical-index-data
A11: 43921 | B11: 8597.75 | C11: =(B11-B10)/B10 -> -0.26033861 | D11: https://www.nseindia.com/reports-indices-historical-index-data
A12: 44286 | B12: 14690.7 | C12: =(B12-B11)/B11 -> 0.70866797 | D12: https://www.nseindia.com/reports-indices-historical-index-data
A13: 44651 | B13: 17464.75 | C13: =(B13-B12)/B12 -> 0.18883035 | D13: https://www.nseindia.com/reports-indices-historical-index-data
B16: 10 Year Average Market Return | C16: =AVERAGE(C4:C13) -> 0.15051788

Sheet 1B. SNIPS OF INPUTS FROM SOURCE
A1: 1B. SNIPS OF THE INPUTS FROM THE RELEVANT SOURCES
A33: Figure 1: Risk Free Rate - 10 Year Government Security Bond Yield from Trading Economics. | L33: Figure 2: Beta value of Dalmia Bharat Limited from MoneyControl. | W33: Figure 3: Corporate Tax Rate | AH33: Figure 4: GDP Growth Rate | AS33: Figure 5: Shares Outstanding from the Annual Report
A38: Scroll to the right.

Sheet 2. RAW FINANCIALS (CASE)
A1: 2. RAW FINANCIALS FROM THE CLSA CASE
A3: Income Statements of Dalmia (2019-2022) in Million Indian Rupees | G3: Figure 3a: Income Statement from the CLSA Case Analysis
A4: Particulars | B4: 2019 | C4: 2020 | D4: 2021 | E4: 2022
A5: Revenue | B5: 94840 | C5: 95810 | D5: 105220 | E5: 112860
A6: Cost of Goods Sold | B6: -21470 | C6: -19970 | D6: -21840 | E6: -19590
A7: Gross Profit | B7: =B5+B6 -> 73370 | C7: =C5+C6 -> 75840 | D7: =D5+D6 -> 83380 | E7: =E5+E6 -> 93270
A8: Research & Development Costs | B8: 0 | C8: 0 | D8: 0 | E8: 0
A9: Selling and Marketing Expenses | B9: 0 | C9: 0 | D9: 0 | E9: 0
A10: Other SG&A | B10: -31490 | C10: -31220 | D10: -30060 | E10: -41010
A11: Other Operating Expenses | B11: -22460 | C11: -23560 | D11: -25490 | E11: -28000
A12: Operating EBITDA | B12: =B7+SUM(B8:B11) -> 19420 | C12: =C7+SUM(C8:C11) -> 21060 | D12: =D7+SUM(D8:D11) -> 27830 | E12: =E7+SUM(E8:E11) -> 24260
A13: Depreciation / Amortization | B13: -12960 | C13: -15280 | D13: -12620 | E13: -12370
A14: Operating EBIT | B14: =B12+B13 -> 6460 | C14: =C12+C13 -> 5780 | D14: =D12+D13 -> 15210 | E14: =E12+E13 -> 11890
A15: Interest Income | B15: 2440 | C15: 2170 | D15: 1820 | E15: 1550
A16: Interest Expense | B16: -5510 | C16: -4380 | D16: -2950 | E16: -1970
A17: Net Interest Income / (Expense) | B17: =B15+B16 -> -3070 | C17: =C15+C16 -> -2210 | D17: =D15+D16 -> -1130 | E17: =E15+E16 -> -420
A18: Associates / Investments | B18: 0 | C18: 0 | D18: 0 | E18: 0
A19: Forex / Other Income | B19: 0 | C19: 0 | D19: 0 | E19: 0
A20: Asset Sales / Other Cash Items | B20: 0 | C20: 0 | D20: 0 | E20: 0
A21: Asset Revaluation / Exceptional Items | B21: 0 | C21: 0 | D21: 0 | E21: 0
A22: Profit Before Tax | B22: =B14+B17 -> 3390 | C22: =C14+C17 -> 3570 | D22: =D14+D17 -> 14080 | E22: =E14+E17 -> 11470
A23: Taxation | B23: 100 | C23: -1190 | D23: -1650 | E23: -3100
A24: Profit After Tax | B24: =B22+B23 -> 3490 | C24: =C22+C23 -> 2380 | D24: =D22+D23 -> 12430 | E24: =E22+E23 -> 8370
A25: Preference Dividends | B25: 0 | C25: 0 | D25: 0 | E25: 0
A26: Profit for Period | B26: =B24+B25 -> 3490 | C26: =C24+C25 -> 2380 | D26: =D24+D25 -> 12430 | E26: =E24+E25 -> 8370
A27: Minority Interest | B27: -410 | C27: -140 | D27: -120 | E27: 3000
A28: Net Profit | B28: =B26+B27 -> 3080 | C28: =C26+C27 -> 2240 | D28: =D26+D27 -> 12310 | E28: =E26+E27 -> 11370
A29: Extraordinaries / Others | B29: 0 | C29: 0 | D29: 0 | E29: 0
A30: Profit Available to Ordinary Shares | B30: =B28+B29 -> 3080 | C30: =C28+C29 -> 2240 | D30: =D28+D29 -> 12310 | E30: =E28+E29 -> 11370
A31: Dividends | B31: -464 | C31: -464 | D31: -373 | E31: -248
A32: Retained Profit | B32: =B30+B31 -> 2616 | C32: =C30+C31 -> 1776 | D32: =D30+D31 -> 11937 | E32: =E30+E31 -> 11122
A33: Adjusted Profit | B33: =B30 -> 3080 | C33: =C30 -> 2240 | D33: =D30 -> 12310 | E33: =E30 -> 11370
A34: EPS (Indian Rupees) | B34: 16 | C34: 11.6 | D34: 65.9 | E34: 60.9
A35: Adjusted EPS (Pre Except) (Indian Rupees) | B35: 16 | C35: 11.6 | D35: 65.9 | E35: 60.9
A36: Core EPS (Indian Rupees) | B36: 16 | C36: 11.6 | D36: 65.9 | E36: 60.9
A37: DPS (Indian Rupees) | B37: 2 | C37: 2 | D37: 1.3 | E37: 9
A39: Balance Sheet of Dalmia (2019-2022) in Million Indian Rupees | G39: Figure 3b: Income Statement from the CLSA Case Analysis
A40: Cash & Equivalents | B40: 16360 | C40: 22470 | D40: 15290 | E40: 15680
A41: Accounts Receivables | B41: 5490 | C41: 3970 | D41: 6880 | E41: 6730
A42: Inventories | B42: 10320 | C42: 9740 | D42: 9240 | E42: 9450
...

Sheet 3. KEY ASSUMPTIONS & DRIVERS
A1: 3. KEY ASSUMPTIONS & DRIVERS
A3: 1. Capital Expenditure (CAPEX)
A4: A. Capital expenditure is assumed to grow at 1% year-on-year, based on the previous year’s capex, as per the assignment guidelines.
A5: B. No separate PPE schedule has been prepared as per the assignment guidelines.
A7: 2. Depreciation
A8: A. Depreciation expense is assumed to remain constant over the forecast period.
A9: B. It is calculated as the average of the last four historical years, in line with the instruction to avoid detailed asset roll-forward modelling.
A11: 3. Working Capital
A12: A. Annual changes in working capital are assumed to grow at 2% year-on-year, based on the previous year’s working capital change.
A13: B. No detailed receivables, inventory, or payables schedules have been constructed.
A15: 4. Revenue Growth
A16: A. Revenue is projected to grow at 6.5% annually, derived from India’s GDP growth rate as reported by the World Bank.
... A19: 5. EBIT and Operating Margin
A20: Particulars | B20: 2019 | C20: 2020 | D20: 2021 | E20: 2022
A21: EBIT Margin | B21: ='2. RAW FINANCIALS (CASE)'!B14/'2. RAW FINANCIALS (CASE)'!B5 -> 0.06811472 | C21: ='2. RAW FINANCIALS (CASE)'!C14/'2. RAW FINANCIALS (CASE)'!C5 -> 0.060327732 | D21: ='2. RAW FINANCIALS (CASE)'!D14/'2. RAW FINANCIALS (CASE)'!D5 -> 0.14455427 | E21: ='2. RAW FINANCIALS (CASE)'!E14/'2. RAW FINANCIALS (CASE)'!E5 -> 0.10535176
B23: Average EBIT Margin | D23: =AVERAGE(B21:E21) -> 0.09458712
A25: A. EBIT margins for the forecast period are assumed to remain stable.
A26: B. The margin is calculated as the average historical EBIT margin for the period 2019–2022.
A27: C. Projected EBIT is estimated by applying this average margin to forecast revenues.
A29: 6. Projection Horizon
A30: A. Financial projections have been extended until FCFF becomes positive, resulting in a 25-year operational forecast.
A31: B. However, valuation and discounting are restricted to a 10-year horizon, in accordance with assignment requirements.
A33: 7. Discounting Methodology
A34: A. Free Cash Flows to the Firm (FCFF) are discounted using a uniform WACC-based discount factor, applied consistently across the valuation horizon, in line with the reference valuation framework provided.
A37: 8. Terminal Growth Rate
A38: A. The terminal growth rate is assumed to be 6.5%, aligned with India’s long-term GDP growth expectations as reported by the World Bank.
A39: B. This assumption is applied consistently across all valuation scenarios.
A41: 9. ESG Impact Assumptions
... A47: C. The discount rate and growth assumptions remain unchanged across ESG scenarios.

Sheet 4. FCFF BUILD-UP & SENSITIVITY
A1: 4. FCFF BUILD-UP & SENSITIVITY ANALYSIS
A2: Year Type | B2: Current Year | C2: Projected Year | D2: Projected Year | E2: Projected Year | F2: Projected Year | G2: Projected Year | H2: Projected Year | I2: Projected Year | J2: Projected Year | K2: Projected Year | L2: Projected Year | M2: Projected Year | N2: Projected Year | O2: Projected Year | P2: Projected Year | Q2: Projected Year | R2: Projected Year | S2: Projected Year | T2: Projected Year | U2: Projected Year | V2: Projected Year | W2: Projected Year | X2: Projected Year | Y2: Projected Year | Z2: Projected Year | AA2: Projected Year
A3: Year | B3: 2022 | C3: =B3+1 -> 2023 | D3: =C3+1 -> 2024 | E3: =D3+1 -> 2025 | F3: =E3+1 -> 2026 | G3: =F3+1 -> 2027 | H3: =G3+1 -> 2028 | I3: =H3+1 -> 2029 | J3: =I3+1 -> 2030 | ... AA3: =Z3+1 -> 2047
A4: Revenue (₹ Lakhs) | B4: ='2. RAW FINANCIALS (CASE)'!E5 -> 112860 | C4: =B4*(1+'1. INPUTS'!$B$19) -> 120195.9 | D4: =C4*(1+'1. INPUTS'!$B$19) -> 128008.63 | E4: =D4*(1+'1. INPUTS'!$B$19) -> 136329.19 | F4: =E4*(1+'1. INPUTS'!$B$19) -> 145190.59 | G4: =F4*(1+'1. INPUTS'!$B$19) -> 154627.98 | H4: =G4*(1+'1. INPUTS'!$B$19) -> 164678.8 | I4: =H4*(1+'1. INPUTS'!$B$19) -> 175382.92 | J4: =I4*(1+'1. INPUTS'!$B$19) -> 186782.81 | ... AA4: =Z4*(1+'1. INPUTS'!$B$19) -> 544854.12
A5: EBIT (₹ Lakhs) | B5: ='2. RAW FINANCIALS (CASE)'!E14 -> 11890 | C5: =C4*'3. KEY ASSUMPTIONS & DRIVERS'!$D$23 -> 11368.984 | D5: =D4*'3. KEY ASSUMPTIONS & DRIVERS'!$D$23 -> 12107.968 | E5: =E4*'3. KEY ASSUMPTIONS & DRIVERS'!$D$23 -> 12894.986 | F5: =F4*'3. KEY ASSUMPTIONS & DRIVERS'!$D$23 -> 13733.16 | G5: =G4*'3. KEY ASSUMPTIONS & DRIVERS'!$D$23 -> 14625.815 | H5: =H4*'3. KEY ASSUMPTIONS & DRIVERS'!$D$23 -> 15576.493 | I5: =I4*'3. KEY ASSUMPTIONS & DRIVERS'!$D$23 -> 16588.966 | J5: =J4*'3. KEY ASSUMPTIONS & DRIVERS'!$D$23 -> 17667.248 | ... AA5: =AA4*'3. KEY ASSUMPTIONS & DRIVERS'!$D$23 -> 51536.182
A6: Depreciation (₹ Lakhs) | B6: =-'2. RAW FINANCIALS (CASE)'!E13 -> 12370 | C6: =-AVERAGE('2. RAW FINANCIALS (CASE)'!B13:E13) -> 13307.5 | D6: {=AVERAGE(C6,-'2. RAW FINANCIALS (CASE)'!C13:E13)} -> 13394.375 | E6: {=AVERAGE(C6:D6,-'2. RAW FINANCIALS (CASE)'!D13:E13)} -> 12922.969 | F6: =AVERAGE(B6:E6) -> 12998.711 | G6: =AVERAGE(C6:F6) -> 13155.889 | H6: =AVERAGE(D6:G6) -> 13117.986 | I6: =AVERAGE(E6:H6) -> 13048.889 | J6: =AVERAGE(F6:I6) -> 13080.368 | K6: =AVERAGE(G6:J6) -> 13100.783 | L6: =AVERAGE(H6:K6) -> 13087.006 | M6: =AVERAGE(I6:L6) -> 13079.262 | ... AA6: =AVERAGE(W6:Z6) -> 13085.999
A7: CAPEX (₹ Lakhs) | B7: ='4A. CAPEX & WC WORKINGS'!E18 -> 18600 | C7: =B7*(1+'1. INPUTS'!$B$26) -> 18786 | D7: =C7*(1+'1. INPUTS'!$B$26) -> 18973.86 | E7: =D7*(1+'1. INPUTS'!$B$26) -> 19163.599 | F7: =E7*(1+'1. INPUTS'!$B$26) -> 19355.235 | G7: =F7*(1+'1. INPUTS'!$B$26) -> 19548.787 | H7: =G7*(1+'1. INPUTS'!$B$26) -> 19744.275 | I7: =H7*(1+'1. INPUTS'!$B$26) -> 19941.718 | J7: =I7*(1+'1. INPUTS'!$B$26) -> 20141.135 | ... AA7: =Z7*(1+'1. INPUTS'!$B$26) -> 23853.235
A8: Change in Working Capital (₹ Lakhs) | B8: ='4A. CAPEX & WC WORKINGS'!E14 -> 9260 | C8: =B8*(1+'1. INPUTS'!$B$27) -> 9445.2 | D8: =C8*(1+'1. INPUTS'!$B$27) -> 9634.104 | E8: =D8*(1+'1. INPUTS'!$B$27) -> 9826.7861 | F8: =E8*(1+'1. INPUTS'!$B$27) -> 10023.322 | G8: =F8*(1+'1. INPUTS'!$B$27) -> 10223.788 | H8: =G8*(1+'1. INPUTS'!$B$27) -> 10428.264 | I8: =H8*(1+'1. INPUTS'!$B$27) -> 10636.829 | J8: =I8*(1+'1. INPUTS'!$B$27) -> 10849.566 | ... AA8: =Z8*(1+'1. INPUTS'!$B$27) -> 15192.012
A9: Net Profit After Tax (₹ Lakhs) | B9: ='2. RAW FINANCIALS (CASE)'!E24 -> 8370 | C9: =C5*(1-'1. INPUTS'!$B$11) -> 8526.7381 | D9: =D5*(1-'1. INPUTS'!$B$11) -> 9080.976 | E9: =E5*(1-'1. INPUTS'!$B$11) -> 9671.2395 | F9: =F5*(1-'1. INPUTS'!$B$11) -> 10299.87 | G9: =G5*(1-'1. INPUTS'!$B$11) -> 10969.362 | H9: =H5*(1-'1. INPUTS'!$B$11) -> 11682.37 | I9: =I5*(1-'1. INPUTS'!$B$11) -> 12441.724 | J9: =J5*(1-'1. INPUTS'!$B$11) -> 13250.436 | ... AA9: =AA5*(1-'1. INPUTS'!$B$11) -> 38652.137
A10: FCFF (₹ Lakhs) | B10: =B9+B6-B7-B8 -> -7120 | C10: =C9+C6-C7-C8 -> -6396.9619 | D10: =D9+D6-D7-D8 -> -6132.613 | E10: =E9+E6-E7-E8 -> -6396.1765 | F10: =F9+F6-F7-F8 -> -6079.9754 | G10: =G9+G6-G7-G8 -> -5647.3249 | H10: =H9+H6-H7-H8 -> -5372.1829 | I10: =I9+I6-I7-I8 -> -5087.9341 | ... AA10: =AA9+AA6-AA7-AA8 -> 12692.889
A11: Discount Factor | B11: =1/(1+'1. INPUTS'!$B$17)^1 -> 0.89230529 | C11: =1/(1+'1. INPUTS'!$B$17)^1 -> 0.89230529 | D11: =1/(1+'1. INPUTS'!$B$17)^1 -> 0.89230529 | E11: =1/(1+'1. INPUTS'!$B$17)^1 -> 0.89230529 | F11: =1/(1+'1. INPUTS'!$B$17)^1 -> 0.89230529 | G11: =1/(1+'1. INPUTS'!$B$17)^1 -> 0.89230529 | H11: =1/(1+'1. INPUTS'!$B$17)^1 -> 0.89230529 | I11: =1/(1+'1. INPUTS'!$B$17)^1 -> 0.89230529 | ... AA11: =1/(1+'1. INPUTS'!$B$17)^1 -> 0.89230529
A12: Present Value (₹ Lakhs) | B12: =B10*B11 -> -6353.2137 | C12: =C10*C11 -> -5708.043 | D12: =D10*D11 -> -5472.163 | E12: =E10*E11 -> -5707.3421 | F12: =F10*F11 -> -5425.1942 | G12: =G10*G11 -> -5039.1379 | H12: =H10*H11 -> -4793.6272 | I12: =I10*I11 -> -4539.9905 | ... AA12: =AA10*AA11 -> 11325.932
E14: Sensitivity Analysis
A15: Terminal Value (₹ Lakhs) | B15: =AA10*(1+B22)/(B21-B22) -> 242723.63
A16: PV of Terminal Value (₹ Lakhs) | B16: =B15/(1+B21)^COUNT(C3:AA3) -> 14058.817 | H16: WACC
A17: Enterprise Value (₹ Lakhs) | B17: =B16+SUM(C12:AA12) -> 10945.102 | H17: WACC (-0.5%) | I17: WACC (Base) | J17: WACC (+0.5%)
A18: No: of shares outstanding (In Lakhs) | B18: ='1. INPUTS'!B20 -> 1875.6516 | G18: =B17/B18 -> 5.8353597 | H18: 0.1157 | I18: ='1. INPUTS'!B17 -> 0.12069267 | J18: 0.1257
A19: Intrinsic Value Per Share (₹) | B19: =B17/B18 -> 5.8353597 | E19: Growth | F19: Growth (-0.5%) | G19: 0.06 | H19: 6.6800654 | I19: 5.1855783 | J19: 3.9968765
F20: Growth (Base) | G20: 0.065 | H20: 7.545784 | I20: 5.8353597 | J20: 4.4917342
A21: WACC | B21: ='1. INPUTS'!B8*'1. INPUTS'!B14+'1. INPUTS'!B12*'1. INPUTS'!B15 -> 0.12069267 | F21: Growth (+0.5%) | G21: 0.07 | H21: 8.6009378 | I21: 6.6133217 | J21: 5.0754352
A22: Growth Rate | B22: ='1. INPUTS'!B19 -> 0.065
E25: Case Type | F25: WACC | G25: Growth Rate | H25: Value per Share
E26: Worst Case | F26: 0.1107 | G26: 0.06 | H26: =J19 -> 3.9968765
E27: Weak Case | F27: 0.1107 | G27: 0.065 | H27: =J20 -> 4.4917342
E28: Base Case | F28: 0.1057 | G28: 0.065 | H28: =I20 -> 5.8353597
E29: Strong Case | F29: 0.1057 | G29: 0.07 | H29: =H20 -> 7.545784
E30: Best Case | F30: 0.1007 | G30: 0.07 | H30: =H21 -> 8.6009378
A31: Scroll to the right.

Sheet 4A. CAPEX & WC WORKINGS
A1: 4A. CAPEX & WC WORKINGS
B2: Values in Lakhs
A3: Particulars | B3: 2019 | C3: 2020 | D3: 2021 | E3: 2022
A4: ='2. RAW FINANCIALS (CASE)'!A45 -> Fixed Assets | B4: ='2. RAW FINANCIALS (CASE)'!B45 -> 95870 | C4: ='2. RAW FINANCIALS (CASE)'!C45 -> 102890 | D4: ='2. RAW FINANCIALS (CASE)'!D45 -> 110570 | E4: ='2. RAW FINANCIALS (CASE)'!E45 -> 116800
A5: ='2. RAW FINANCIALS (CASE)'!A44 -> Current Assets | B5: ='2. RAW FINANCIALS (CASE)'!B44 -> 51880 | C5: ='2. RAW FINANCIALS (CASE)'!C44 -> 53440 | D5: ='2. RAW FINANCIALS (CASE)'!D44 -> 48630 | E5: ='2. RAW FINANCIALS (CASE)'!E44 -> 55200
A6: ='2. RAW FINANCIALS (CASE)'!A57 -> Current Liabilities | B6: ='2. RAW FINANCIALS (CASE)'!B57 -> 44650 | C6: ='2. RAW FINANCIALS (CASE)'!C57 -> 51030 | D6: ='2. RAW FINANCIALS (CASE)'!D57 -> 53000 | E6: ='2. RAW FINANCIALS (CASE)'!E57 -> 50310
A7: ='2. RAW FINANCIALS (CASE)'!A13 -> Depreciation / Amortization | B7: =-'2. RAW FINANCIALS (CASE)'!B13 -> 12960 | C7: =-'2. RAW FINANCIALS (CASE)'!C13 -> 15280 | D7: =-'2. RAW FINANCIALS (CASE)'!D13 -> 12620 | E7: =-'2. RAW FINANCIALS (CASE)'!E13 -> 12370
A8: ='2. RAW FINANCIALS (CASE)'!A70 -> Total Debt | B8: ='2. RAW FINANCIALS (CASE)'!B70 -> 60070 | C8: ='2. RAW FINANCIALS (CASE)'!C70 -> 60900 | D8: ='2. RAW FINANCIALS (CASE)'!D70 -> 38480 | E8: ='2. RAW FINANCIALS (CASE)'!E70 -> 32440
A9: ='2. RAW FINANCIALS (CASE)'!A40 -> Cash & Equivalents | B9: ='2. RAW FINANCIALS (CASE)'!B40 -> 16360 | C9: ='2. RAW FINANCIALS (CASE)'!C40 -> 22470 | D9: ='2. RAW FINANCIALS (CASE)'!D40 -> 15290 | E9: ='2. RAW FINANCIALS (CASE)'!E40 -> 15680
A11: Net Working Capital
A12: Particulars | B12: 2019 | C12: 2020 | D12: 2021 | E12: 2022
A13: Working Capital (₹ Lakhs) | B13: ='4A. CAPEX & WC WORKINGS'!B5-'4A. CAPEX & WC WORKINGS'!B6 -> 7230 | C13: ='4A. CAPEX & WC WORKINGS'!C5-'4A. CAPEX & WC WORKINGS'!C6 -> 2410 | D13: ='4A. CAPEX & WC WORKINGS'!D5-'4A. CAPEX & WC WORKINGS'!D6 -> -4370 | E13: ='4A. CAPEX & WC WORKINGS'!E5-'4A. CAPEX & WC WORKINGS'!E6 -> 4890 | F13: (Current Assets - Current Liabilities)
A14: Change in Working Capital (₹ Lakhs) | B14: =0-B13 -> -7230 | C14: =C13-B13 -> -4820 | D14: =D13-C13 -> -6780 | E14: =E13-D13 -> 9260 | F14: (Current Year - Previous Year)
A16: Capital Expenditure
A17: Particulars | B17: 2019 | C17: 2020 | D17: 2021 | E17: 2022
A18: Capex Working (₹ Lakhs) | B18: 0 | C18: =C4-B4+C7 -> 22300 | D18: =D4-C4+D7 -> 20300 | E18: =E4-D4+E7 -> 18600 | F18: (Capex = Closing Fixed Assets - Opening Fixed Assets + Depreciation)

Sheet 5A. MILD ESG SCENARIO
A1: 5A. MILD ESG SCENARIO
A2: Year Type | B2: Projected Year | C2: Projected Year | D2: Projected Year | E2: Projected Year | F2: Projected Year | G2: Projected Year | H2: Projected Year | I2: Projected Year | J2: Projected Year | K2: Projected Year | L2: Projected Year | M2: Projected Year | N2: Projected Year | O2: Projected Year | P2: Projected Year | Q2: Projected Year | R2: Projected Year | S2: Projected Year | T2: Projected Year | U2: Projected Year | V2: Projected Year | W2: Projected Year | X2: Projected Year | Y2: Projected Year | Z2: Projected Year
A3: Year | B3: =2022+1 -> 2023 | C3: =B3+1 -> 2024 | D3: =C3+1 -> 2025 | E3: =D3+1 -> 2026 | F3: =E3+1 -> 2027 | G3: =F3+1 -> 2028 | H3: =G3+1 -> 2029 | I3: =H3+1 -> 2030 | J3: =I3+1 -> 2031 | ... Z3: =Y3+1 -> 2047
A4: FCFF (₹ Lakhs) | B4: ='4. FCFF BUILD-UP & SENSITIVITY'!C10 -> -6396.9619 | C4: ='4. FCFF BUILD-UP & SENSITIVITY'!D10 -> -6132.613 | D4: ='4. FCFF BUILD-UP & SENSITIVITY'!E10 -> -6396.1765 | E4: ='4. FCFF BUILD-UP & SENSITIVITY'!F10 -> -6079.9754 | F4: ='4. FCFF BUILD-UP & SENSITIVITY'!G10 -> -5647.3249 | G4: ='4. FCFF BUILD-UP & SENSITIVITY'!H10 -> -5372.1829 | H4: ='4. FCFF BUILD-UP & SENSITIVITY'!I10 -> -5087.9341 | I4: ='4. FCFF BUILD-UP & SENSITIVITY'!J10 -> -4659.8959 | ... Z4: ='4. FCFF BUILD-UP & SENSITIVITY'!AA10 -> 12692.889
A5: ESG FCFF (₹ Lakhs) | B5: =B4*(1-'1. INPUTS'!$B$22) -> -6077.1138 | C5: =C4*(1-'1. INPUTS'!$B$22) -> -5825.9823 | D5: =D4*(1-'1. INPUTS'!$B$22) -> -6076.3676 | E5: =E4*(1-'1. INPUTS'!$B$22) -> -5775.9766 | F5: =F4*(1-'1. INPUTS'!$B$22) -> -5364.9587 | G5: =G4*(1-'1. INPUTS'!$B$22) -> -5103.5737 | H5: =H4*(1-'1. INPUTS'!$B$22) -> -4833.5374 | I5: =I4*(1-'1. INPUTS'!$B$22) -> -4426.9011 | ... Z5: =Z4*(1-'1. INPUTS'!$B$22) -> 12058.245
A6: Discount Factor | B6: =1/(1+'1. INPUTS'!$B$17)^1 -> 0.89230529 | C6: =1/(1+'1. INPUTS'!$B$17)^1 -> 0.89230529 | D6: =1/(1+'1. INPUTS'!$B$17)^1 -> 0.89230529 | E6: =1/(1+'1. INPUTS'!$B$17)^1 -> 0.89230529 | F6: =1/(1+'1. INPUTS'!$B$17)^1 -> 0.89230529 | G6: =1/(1+'1. INPUTS'!$B$17)^1 -> 0.89230529 | H6: =1/(1+'1. INPUTS'!$B$17)^1 -> 0.89230529 | I6: =1/(1+'1. INPUTS'!$B$17)^1 -> 0.89230529 | ... Z6: =1/(1+'1. INPUTS'!$B$17)^1 -> 0.89230529
A7: Present Value (₹ Lakhs) | B7: =B5*B6 -> -5422.6408 | C7: =C5*C6 -> -5198.5549 | D7: =D5*D6 -> -5421.975 | E7: =E5*E6 -> -5153.9345 | F7: =F5*F6 -> -4787.181 | G7: =G5*G6 -> -4553.9458 | H7: =H5*H6 -> -4312.991 | I7: =I5*I6 -> -3950.1473 | ... Z7: =Z5*Z6 -> 10759.636
A9: Terminal Value (₹ Lakhs) | B9: =Z5*(1+B16)/(B15-B16) -> 230587.45
A10: PV of Terminal Value (₹ Lakhs) | B10: =B9/(1+B15)^COUNT(B3:Z3) -> 13355.876
A11: Enterprise Value (₹ Lakhs) | B11: =B10+SUM(B7:Z7) -> 10397.847
A12: No: of shares outstanding (₹ Lakhs) | B12: ='1. INPUTS'!B20 -> 1875.6516
A13: Intrinsic Value Per Share (₹) | B13: =B11/B12 -> 5.5435917
A15: WACC | B15: ='4. FCFF BUILD-UP & SENSITIVITY'!B21 -> 0.12069267
A16: Growth Rate | B16: ='4. FCFF BUILD-UP & SENSITIVITY'!B22 -> 0.065
A17: Scroll to the right.

Sheet 5B. MODERATE ESG SCENARIO
A1: 5B. MODERATE ESG SCENARIO
A2: Year Type | B2: Projected Year | C2: Projected Year | D2: Projected Year | E2: Projected Year | F2: Projected Year | G2: Projected Year | H2: Projected Year | I2: Projected Year | J2: Projected Year | K2: Projected Year | L2: Projected Year | M2: Projected Year | N2: Projected Year | O2: Projected Year | P2: Projected Year | Q2: Projected Year | R2: Projected Year | S2: Projected Year | T2: Projected Year | U2: Projected Year | V2: Projected Year | W2: Projected Year | X2: Projected Year | Y2: Projected Year | Z2: Projected Year
A3: Year | B3: =2022+1 -> 2023 | C3: =B3+1 -> 2024 | D3: =C3+1 -> 2025 | E3: =D3+1 -> 2026 | F3: =E3+1 -> 2027 | G3: =F3+1 -> 2028 | H3: =G3+1 -> 2029 | I3: =H3+1 -> 2030 | J3: =I3+1 -> 2031 | ... Z3: =Y3+1 -> 2047
A4: FCFF (₹ Lakhs) | B4: ='4. FCFF BUILD-UP & SENSITIVITY'!C10 -> -6396.9619 | C4: ='4. FCFF BUILD-UP & SENSITIVITY'!D10 -> -6132.613 | D4: ='4. FCFF BUILD-UP & SENSITIVITY'!E10 -> -6396.1765 | E4: ='4. FCFF BUILD-UP & SENSITIVITY'!F10 -> -6079.9754 | F4: ='4. FCFF BUILD-UP & SENSITIVITY'!G10 -> -5647.3249 | G4: ='4. FCFF BUILD-UP & SENSITIVITY'!H10 -> -5372.1829 | H4: ='4. FCFF BUILD-UP & SENSITIVITY'!I10 -> -5087.9341 | I4: ='4. FCFF BUILD-UP & SENSITIVITY'!J10 -> -4659.8959 | ... Z4: ='4. FCFF BUILD-UP & SENSITIVITY'!AA10 -> 12692.889
A5: ESG FCFF (₹ Lakhs) | B5: =B4*(1-'1. INPUTS'!$B$23) -> -5437.4177 | C5: =C4*(1-'1. INPUTS'!$B$23) -> -5212.721 | D5: =D4*(1-'1. INPUTS'!$B$23) -> -5436.75 | E5: =E4*(1-'1. INPUTS'!$B$23) -> -5167.9791 | F5: =F4*(1-'1. INPUTS'!$B$23) -> -4800.2262 | G5: =G4*(1-'1. INPUTS'!$B$23) -> -4566.3554 | H5: =H4*(1-'1. INPUTS'!$B$23) -> -4324.744 | I5: =I4*(1-'1. INPUTS'!$B$23) -> -3960.9115 | ... Z5: =Z4*(1-'1. INPUTS'!$B$23) -> 10788.956
A6: Discount Factor | B6: =1/(1+'1. INPUTS'!$B$17)^1 -> 0.89230529 | C6: =1/(1+'1. INPUTS'!$B$17)^1 -> 0.89230529 | D6: =1/(1+'1. INPUTS'!$B$17)^1 -> 0.89230529 | E6: =1/(1+'1. INPUTS'!$B$17)^1 -> 0.89230529 | F6: =1/(1+'1. INPUTS'!$B$17)^1 -> 0.89230529 | G6: =1/(1+'1. INPUTS'!$B$17)^1 -> 0.89230529 | H6: =1/(1+'1. INPUTS'!$B$17)^1 -> 0.89230529 | I6: =1/(1+'1. INPUTS'!$B$17)^1 -> 0.89230529 | ... Z6: =1/(1+'1. INPUTS'!$B$17)^1 -> 0.89230529
A7: Present Value (₹ Lakhs) | B7: =B5*B6 -> -4851.8365 | C7: =C5*C6 -> -4651.3386 | D7: =D5*D6 -> -4851.2408 | E7: =E5*E6 -> -4611.4151 | F7: =F5*F6 -> -4283.2672 | G7: =G5*G6 -> -4074.5831 | H7: =H5*H6 -> -3858.992 | I7: =I5*I6 -> -3534.3423 | ... Z7: =Z5*Z6 -> 9627.0424
A9: Terminal Value (₹ Lakhs) | B9: =Z5*(1+B16)/(B15-B16) -> 206315.09
A10: PV of Terminal Value (₹ Lakhs) | B10: =B9/(1+B15)^COUNT(B3:Z3) -> 11949.994
A11: Enterprise Value (₹ Lakhs) | B11: =B10+SUM(B7:Z7) -> 9303.3366
A12: No: of shares outstanding (₹ Lakhs) | B12: ='1. INPUTS'!B20 -> 1875.6516
A13: Intrinsic Value Per Share (₹) | B13: =B11/B12 -> 4.9600558
A15: WACC | B15: ='4. FCFF BUILD-UP & SENSITIVITY'!B21 -> 0.12069267
A16: Growth Rate | B16: ='4. FCFF BUILD-UP & SENSITIVITY'!B22 -> 0.065
A17: Scroll to the right.

Sheet 5C. SEVERE ESG SCENARIO
A1: 5C. SEVERE ESG SCENARIO
A2: Year Type | B2: Projected Year | C2: Projected Year | D2: Projected Year | E2: Projected Year | F2: Projected Year | G2: Projected Year | H2: Projected Year | I2: Projected Year | J2: Projected Year | K2: Projected Year | L2: Projected Year | M2: Projected Year | N2: Projected Year | O2: Projected Year | P2: Projected Year | Q2: Projected Year | R2: Projected Year | S2: Projected Year | T2: Projected Year | U2: Projected Year | V2: Projected Year | W2: Projected Year | X2: Projected Year | Y2: Projected Year | Z2: Projected Year
A3: Year | B3: =2022+1 -> 2023 | C3: =B3+1 -> 2024 | D3: =C3+1 -> 2025 | E3: =D3+1 -> 2026 | F3: =E3+1 -> 2027 | G3: =F3+1 -> 2028 | H3: =G3+1 -> 2029 | I3: =H3+1 -> 2030 | J3: =I3+1 -> 2031 | ... Z3: =Y3+1 -> 2047
A4: FCFF (₹ Lakhs) | B4: ='4. FCFF BUILD-UP & SENSITIVITY'!C10 -> -6396.9619 | C4: ='4. FCFF BUILD-UP & SENSITIVITY'!D10 -> -6132.613 | D4: ='4. FCFF BUILD-UP & SENSITIVITY'!E10 -> -6396.1765 | E4: ='4. FCFF BUILD-UP & SENSITIVITY'!F10 -> -6079.9754 | F4: ='4. FCFF BUILD-UP & SENSITIVITY'!G10 -> -5647.3249 | G4: ='4. FCFF BUILD-UP & SENSITIVITY'!H10 -> -5372.1829 | H4: ='4. FCFF BUILD-UP & SENSITIVITY'!I10 -> -5087.9341 | I4: ='4. FCFF BUILD-UP & SENSITIVITY'!J10 -> -4659.8959 | ... Z4: ='4. FCFF BUILD-UP & SENSITIVITY'!AA10 -> 12692.889
A5: ESG FCFF (₹ Lakhs) | B5: =B4*(1-'1. INPUTS'!$B$24) -> -4797.7215 | C5: =C4*(1-'1. INPUTS'!$B$24) -> -4599.4597 | D5: =D4*(1-'1. INPUTS'!$B$24) -> -4797.1323 | E5: =E4*(1-'1. INPUTS'!$B$24) -> -4559.9816 | F5: =F4*(1-'1. INPUTS'!$B$24) -> -4235.4937 | G5: =G4*(1-'1. INPUTS'!$B$24) -> -4029.1372 | H5: =H4*(1-'1. INPUTS'!$B$24) -> -3815.9506 | I5: =I4*(1-'1. INPUTS'!$B$24) -> -3494.9219 | ... Z5: =Z4*(1-'1. INPUTS'!$B$24) -> 9519.6669
A6: Discount Factor | B6: =1/(1+'1. INPUTS'!$B$17)^1 -> 0.89230529 | C6: =1/(1+'1. INPUTS'!$B$17)^1 -> 0.89230529 | D6: =1/(1+'1. INPUTS'!$B$17)^1 -> 0.89230529 | E6: =1/(1+'1. INPUTS'!$B$17)^1 -> 0.89230529 | F6: =1/(1+'1. INPUTS'!$B$17)^1 -> 0.89230529 | G6: =1/(1+'1. INPUTS'!$B$17)^1 -> 0.89230529 | H6: =1/(1+'1. INPUTS'!$B$17)^1 -> 0.89230529 | I6: =1/(1+'1. INPUTS'!$B$17)^1 -> 0.89230529 | ... Z6: =1/(1+'1. INPUTS'!$B$17)^1 -> 0.89230529
A7: Present Value (₹ Lakhs) | B7: =B5*B6 -> -4281.0322 | C7: =C5*C6 -> -4104.1223 | D7: =D5*D6 -> -4280.5066 | E7: =E5*E6 -> -4068.8957 | F7: =F5*F6 -> -3779.3534 | G7: =G5*G6 -> -3595.2204 | H7: =H5*H6 -> -3404.9929 | I7: =I5*I6 -> -3118.5373 | ... Z7: =Z5*Z6 -> 8494.4491
A9: Terminal Value (₹ Lakhs) | B9: =Z5*(1+B16)/(B15-B16) -> 182042.72
A10: PV of Terminal Value (₹ Lakhs) | B10: =B9/(1+B15)^COUNT(B3:Z3) -> 10544.113
A11: Enterprise Value (₹ Lakhs) | B11: =B10+SUM(B7:Z7) -> 8208.8264
A12: No: of shares outstanding (₹ Lakhs) | B12: ='1. INPUTS'!B20 -> 1875.6516
A13: Intrinsic Value Per Share (₹) | B13: =B11/B12 -> 4.3765198
A15: WACC | B15: ='4. FCFF BUILD-UP & SENSITIVITY'!B21 -> 0.12069267
A16: Growth Rate | B16: ='4. FCFF BUILD-UP & SENSITIVITY'!B22 -> 0.065
A18: Scroll to the right.

Sheet 6. EXECUTIVE SUMMARY
A1: 6. EXECUTIVE SUMMARY
A2: A. This study evaluates the equity value of Dalmia Bharat Limited by integrating Environmental, Social, and Governance (ESG) considerations into a Discounted Cash Flow (DCF) framework, in line with the principles of sustainable finance and responsible investment.
A4: B. A Free Cash Flow to the Firm (FCFF)–based valuation approach is adopted, with cash flows projected over an extended horizon to capture the firm’s operational recovery.
A6: C. Key valuation inputs include the Weighted Average Cost of Capital (WACC) derived using the Capital Asset Pricing Model (CAPM), a GDP-linked growth assumption, and operating projections based on historical performance and faculty-specified modelling constraints.
A8: D. ESG considerations are incorporated through explicit reductions in FCFF, reflecting the short-term financial impact of sustainability-related investments and compliance costs. Three ESG scenarios are analysed:
A10: i. Mild impact: 5% reduction in FCFF
A11: ii. Moderate impact: 15% reduction in FCFF
A12: iii. Severe impact: 25% reduction in FCFF
A13: E. The valuation results indicate that ESG investments lead to a progressive reduction in equity value in the short term, with the impact becoming more pronounced under moderate and severe scenarios.
A15: F. Sensitivity analysis reveals that the firm’s valuation is more sensitive to changes in the discount rate than to growth assumptions, highlighting the importance of cost of capital considerations in long-term valuation.
A17: G. Despite the short-term valuation impact, ESG integration is viewed as a strategic investment that enhances long-term business resilience, regulatory alignment, and sustainability, particularly in a carbon-intensive sector such as cement.
A19: H. Overall, the analysis demonstrates that while ESG investments may appear value-reducing in the near term, they are critical for long-term value preservation and responsible capital allocation, supporting the case for ESG integration in equity valuation.
