Workbook

Sheet Cover Page
A1: S.No | B1: Name | C1: Nifty 100 Company Name - Part 1 | D1: Nifty 100 Company Name - Part 2
A2: 1 | B2: Abhimanyu Babbar | C2: ='Nifty 100 List'!A48 -> ITC Ltd. | D2: ='Nifty 100 List'!A70 -> Oil & Natural Gas Corporation Ltd.

Sheet Read Me
A1: Read Me Section
A2: This Financial Modeling project consists of two parts:
A4: 1) DCF Valuation (ITC Limited):
A5: Fundamental analysis and intrinsic value estimation using the Discounted Cash Flow (DCF) model.
A6: Includes financial statement building, assumptions, projections, WACC, terminal value, and final valuation to determine if the stock is undervalued or overvalued.
A9: 2) CAPM Modeling (ONGC Limited):
A10: Capital Asset Pricing Model (CAPM) to calculate expected stock returns.
A11: Involves downloading daily prices, calculating returns, running a regression, and deriving the CAPM equation.
A14: Tab - Colour | B14: What does it indicate?
B15: General tabs
B16: DCF - Part 1
B17: CAPM - Part 2
A19: Colour Code | B19: What does it indicate?
A20: XX | B20: Solution of the Assignment.
A21: XX | B21: Projected Data - Calculated
A22: XX | B22: General Headers
B23: DCF - Headers
B24: Sub - Headers
A25: Manual Input | B25: Manual Input

Sheet Contents
A1: S.No | B1: Topic | C1: Tab Link
A2: 1 | B2: Nifty 100 List | C2: Nifty 100 List
A3: 2 | B3: Part 1 - Summary | C3: 1. Part 1 - Summary
A4: 3 | B4: Part 1A - DCF (1.1, 1.2, 1.3 and 1.4) | C4: 1. Part 1A - DCF
A5: 4 | B5: Part 1B - DCF (1.5, 1.6, 1.7 and 1.8) | C5: 1. Part 1B - DCF
A6: 5 | B6: ITC Limited Income Statement | C6: ITC Limited Income Statement
A7: 6 | B7: ITC Limited Balance Sheet | C7: ITC Limited Balance Sheet
A8: 7 | B8: Part 2 - CAPM - 2.1, 2.2, 2.3 | C8: Part 2 - CAPM 2.1, 2.2 and 2.3
A9: 8 | B9: Part 2 - CAPM - 2.4 | C9: Part 2 - CAPM 2.4
A10: 9 | B10: Part 2 - CAPM - 2.5 | C10: Part 2 - CAPM 2.5

Sheet Nifty 100 List
A1: Company Name | B1: Industry | C1: Symbol | D1: Series | E1: ISIN Code
A2: ABB India Ltd. | B2: Capital Goods | C2: ABB | D2: EQ | E2: INE117A01022
A3: Adani Energy Solutions Ltd. | B3: Power | C3: ADANIENSOL | D3: EQ | E3: INE931S01010
A4: Adani Enterprises Ltd. | B4: Metals & Mining | C4: ADANIENT | D4: EQ | E4: INE423A01024
A5: Adani Green Energy Ltd. | B5: Power | C5: ADANIGREEN | D5: EQ | E5: INE364U01010
A6: Adani Ports and Special Economic Zone Ltd. | B6: Services | C6: ADANIPORTS | D6: EQ | E6: INE742F01042
A7: Adani Power Ltd. | B7: Power | C7: ADANIPOWER | D7: EQ | E7: INE814H01011
A8: Adani Total Gas Ltd. | B8: Oil Gas & Consumable Fuels | C8: ATGL | D8: EQ | E8: INE399L01023
A9: Ambuja Cements Ltd. | B9: Construction Materials | C9: AMBUJACEM | D9: EQ | E9: INE079A01024
A10: Apollo Hospitals Enterprise Ltd. | B10: Healthcare | C10: APOLLOHOSP | D10: EQ | E10: INE437A01024
A11: Asian Paints Ltd. | B11: Consumer Durables | C11: ASIANPAINT | D11: EQ | E11: INE021A01026
A12: Avenue Supermarts Ltd. | B12: Consumer Services | C12: DMART | D12: EQ | E12: INE192R01011
... A101: Zydus Lifesciences Ltd. | B101: Healthcare | C101: ZYDUSLIFE | D101: EQ | E101: INE010B01027

Sheet 1. Part 1 - Summary
B2: ='Cover Page'!C2:C2 -> ITC Ltd.
B3: Summary Outputs
B5: =Q5 -> SUMMARY VALUES | Q5: SUMMARY VALUES
E7: Trend | G7: =T7 -> 2023 | H7: =U7 -> 2024 | I7: =V7 -> 2025 | J7: =W7 -> 2026 | K7: =X7 -> 2027 | L7: =Y7 -> 2028 | M7: =Z7 -> 2029 | T7: ='1. Part 1A - 3FS'!B3 -> 2023 | U7: ='1. Part 1A - 3FS'!C3 -> 2024 | V7: ='1. Part 1A - 3FS'!D3 -> 2025 | W7: ='1. Part 1A - 3FS'!E3 -> 2026 | X7: ='1. Part 1A - 3FS'!F3 -> 2027 | Y7: ='1. Part 1A - 3FS'!G3 -> 2028 | Z7: ='1. Part 1A - 3FS'!H3 -> 2029
C8: Income Statement Items
C10: =R10 -> Sales | D10: =S10 -> (₹) | G10: =T10 -> 72917.34 | H10: =U10 -> 73608.84 | I10: =V10 -> 78761.459 | J10: =W10 -> 84274.761 | K10: =X10 -> 90173.994 | L10: =Y10 -> 96486.174 | M10: =Z10 -> 103240.21 | R10: Sales | S10: (₹) | T10: ='1. Part 1A - 3FS'!B28 -> 72917.34 | U10: ='1. Part 1A - 3FS'!C28 -> 73608.84 | V10: ='1. Part 1A - 3FS'!D28 -> 78761.459 | W10: ='1. Part 1A - 3FS'!E28 -> 84274.761 | X10: ='1. Part 1A - 3FS'!F28 -> 90173.994 | Y10: ='1. Part 1A - 3FS'!G28 -> 96486.174 | Z10: ='1. Part 1A - 3FS'!H28 -> 103240.21
C11: =R11 -> Growth | D11: =S11 -> (%) | G11: =T11 -> 0.16659457 | H11: =U11 -> 0.009483341 | I11: =V11 -> 0.07 | J11: =W11 -> 0.07 | K11: =X11 -> 0.07 | L11: =Y11 -> 0.07 | M11: =Z11 -> 0.07 | R11: Growth | S11: (%) | T11: =('ITC Limited Income Statement'!C13-'ITC Limited Income Statement'!D13)/'ITC Limited Income Statement'!D13 -> 0.16659457 | U11: =(U10-T10)/T10 -> 0.009483341 | V11: =(V10-U10)/U10 -> 0.07 | W11: =(W10-V10)/V10 -> 0.07 | X11: =(X10-W10)/W10 -> 0.07 | Y11: =(Y10-X10)/X10 -> 0.07 | Z11: =(Z10-Y10)/Y10 -> 0.07
C14: =R14 -> Operating Profit | D14: =S14 -> (₹) | G14: =T14 -> 25836.41 | H14: =U14 -> 27165.8 | I14: =V14 -> 28354.125 | J14: =W14 -> 30338.914 | K14: =X14 -> 32462.638 | L14: =Y14 -> 34735.023 | M14: =Z14 -> 37166.474 | R14: Operating Profit | S14: (₹) | T14: ='1. Part 1A - 3FS'!B32 -> 25836.41 | U14: ='1. Part 1A - 3FS'!C32 -> 27165.8 | V14: ='1. Part 1A - 3FS'!D32 -> 28354.125 | W14: ='1. Part 1A - 3FS'!E32 -> 30338.914 | X14: ='1. Part 1A - 3FS'!F32 -> 32462.638 | Y14: ='1. Part 1A - 3FS'!G32 -> 34735.023 | Z14: ='1. Part 1A - 3FS'!H32 -> 37166.474
C15: =R15 -> Growth | D15: =S15 -> (%) | G15: =T15 -> 0.24438756 | H15: =U15 -> 0.05145413 | I15: =V15 -> 0.043743426 | J15: =W15 -> 0.07 | K15: =X15 -> 0.07 | L15: =Y15 -> 0.07 | M15: =Z15 -> 0.07 | R15: Growth | S15: (%) | T15: =('ITC Limited Income Statement'!C17-'ITC Limited Income Statement'!D17)/'ITC Limited Income Statement'!D17 -> 0.24438756 | U15: =(U14-T14)/T14 -> 0.05145413 | V15: =(V14-U14)/U14 -> 0.043743426 | W15: =(W14-V14)/V14 -> 0.07 | X15: =(X14-W14)/W14 -> 0.07 | Y15: =(Y14-X14)/X14 -> 0.07 | Z15: =(Z14-Y14)/Y14 -> 0.07
C18: =R18 -> Net Income | G18: =T18 -> 19045.92 | H18: =U18 -> 20473.92 | I18: =V18 -> 19388.224 | J18: =W18 -> 20750.494 | K18: =X18 -> 22208.073 | L18: =Y18 -> 23767.634 | M18: =Z18 -> 25436.314 | R18: Net Income | S18: (₹) | T18: ='1. Part 1A - 3FS'!B38 -> 19045.92 | U18: ='1. Part 1A - 3FS'!C38 -> 20473.92 | V18: ='1. Part 1A - 3FS'!D38 -> 19388.224 | W18: ='1. Part 1A - 3FS'!E38 -> 20750.494 | X18: ='1. Part 1A - 3FS'!F38 -> 22208.073 | Y18: ='1. Part 1A - 3FS'!G38 -> 23767.634 | Z18: ='1. Part 1A - 3FS'!H38 -> 25436.314
C19: =R19 -> Growth | D19: =S19 -> (%) | G19: =T19 -> 0.24951419 | H19: =U19 -> 0.074976688 | I19: =V19 -> -0.053028255 | J19: =W19 -> 0.07026275 | K19: =X19 -> 0.070243123 | L19: =Y19 -> 0.070224945 | M19: =Z19 -> 0.070208109 | R19: Growth | S19: (%) | T19: =('ITC Limited Income Statement'!C24-'ITC Limited Income Statement'!D24)/'ITC Limited Income Statement'!D24 -> 0.24951419 | U19: =(U18-T18)/T18 -> 0.074976688 | V19: =(V18-U18)/U18 -> -0.053028255 | W19: =(W18-V18)/V18 -> 0.07026275 | X19: =(X18-W18)/W18 -> 0.070243123 | Y19: =(Y18-X18)/X18 -> 0.070224945 | Z19: =(Z18-Y18)/Y18 -> 0.070208109

Sheet 1. Part 1A - 3FS
A1: 1.1. THREE FINANCIAL STATEMENTS | B1: 1.4. DEVELOP 5 YEAR FORECASTS
A2: FINANCIAL STATEMENTS | B2: Historical | C2: Historical | D2: Projected | E2: Projected | F2: Projected | G2: Projected | H2: Projected | J2: Notes
A3: ='Cover Page'!C2 -> ITC Ltd. | B3: 2023 | C3: =B3+1 -> 2024 | D3: =C3+1 -> 2025 | E3: =D3+1 -> 2026 | F3: =E3+1 -> 2027 | G3: =F3+1 -> 2028 | H3: =G3+1 -> 2029
A4: (₹) in Crores | I4: X
I5: X
A6: 1.2. ASSUMPTIONS | I6: X
I7: X
A8: INCOME STATEMENT ASSUMPTIONS | I8: X
A9: Revenue Growth % | B9: =('ITC Limited Income Statement'!C7-'ITC Limited Income Statement'!D7)/'ITC Limited Income Statement'!D7 -> 0.17345492 | C9: =(C28-B28)/B28 -> 0.009483341 | D9: =ROUND(AVERAGE('ITC Limited Income Statement'!M13:U13),2) -> 0.07 | E9: =D9 -> 0.07 | F9: =E9 -> 0.07 | G9: =F9 -> 0.07 | H9: =G9 -> 0.07 | I9: X | J9: Average of last 9 years, rounding the number.
A10: Variable Costs as a % of Sales | B10: =B29/B28 -> 0.39778974 | C10: =C29/C28 -> 0.3701622 | D10: =ROUND(AVERAGE('ITC Limited Income Statement'!M14:U14),2) -> 0.37 | E10: =D10 -> 0.37 | F10: =E10 -> 0.37 | G10: =F10 -> 0.37 | H10: =G10 -> 0.37 | I10: X | J10: Average of last 9 years, rounding the number.
A11: Fixed Costs as a % of Sales | B11: =B31/B28 -> 0.24788562 | C11: =C31/C28 -> 0.26078159 | D11: =ROUND(AVERAGE('ITC Limited Income Statement'!M16:U16),2) -> 0.27 | E11: =D11 -> 0.27 | F11: =E11 -> 0.27 | G11: =F11 -> 0.27 | H11: =G11 -> 0.27 | I11: X | J11: Average of last 9 years, rounding the number.
A12: Tax Expense % | B12: =B35/B34 -> 0.25032328 | C12: =C35/C34 -> 0.23550055 | D12: =ROUND(AVERAGE('ITC Limited Income Statement'!M20:U20),2) -> 0.3 | E12: =D12 -> 0.3 | F12: =E12 -> 0.3 | G12: =F12 -> 0.3 | H12: =G12 -> 0.3 | I12: X | J12: Average of last 9 years, rounding the number.
A13: Extraordinary Items as % of EAT before Extraordinary Items | B13: =B37/B36 -> 0.01224047 | C13: =C37/C36 -> 0.012776479 | D13: =ROUND(AVERAGE('ITC Limited Income Statement'!M24:U24),2) -> 0.02 | E13: =ROUND(AVERAGE('ITC Limited Income Statement'!N24:V24),2) -> 0.02 | F13: =ROUND(AVERAGE('ITC Limited Income Statement'!O24:W24),2) -> 0.02 | G13: =ROUND(AVERAGE('ITC Limited Income Statement'!P24:X24),2) -> 0.02 | H13: =ROUND(AVERAGE('ITC Limited Income Statement'!Q24:Y24),2) -> 0.02 | I13: X
I14: X
I15: X
A16: BALANCE SHEET ASSUMPTIONS | I16: X
A17: Current Investments Growth | B17: =('ITC Limited Balance Sheet'!C35-'ITC Limited Balance Sheet'!D35)/'ITC Limited Balance Sheet'!D35 -> 0.40512611 | C17: =('ITC Limited Balance Sheet'!B35-'ITC Limited Balance Sheet'!C35)/'ITC Limited Balance Sheet'!C35 -> -0.24885248 | D17: =ROUND(AVERAGE('ITC Limited Balance Sheet'!M35:U35),2) -> 0.12 | E17: =D17 -> 0.12 | F17: =E17 -> 0.12 | G17: =F17 -> 0.12 | H17: =G17 -> 0.12 | I17: X | J17: Average of last 9 years, rounding the number.
A18: AR Days | B18: =365/(B28/(AVERAGE('ITC Limited Balance Sheet'!C37:D37))) -> 13.56053 | C18: =365/(C28/(AVERAGE('ITC Limited Balance Sheet'!B37:C37))) -> 17.3106 | D18: =C18 -> 17.3106 | E18: =D18 -> 17.3106 | F18: =E18 -> 17.3106 | G18: =F18 -> 17.3106 | H18: =G18 -> 17.3106 | I18: X | J18: From Historical figures.
A19: Inventory Days | B19: =365/(B29/(AVERAGE('ITC Limited Balance Sheet'!C36:D36))) -> 144.00614 | C19: =365/(C29/(AVERAGE('ITC Limited Balance Sheet'!B36:C36))) -> 175.59979 | D19: =C19 -> 175.59979 | E19: =D19 -> 175.59979 | F19: =E19 -> 175.59979 | G19: =F19 -> 175.59979 | H19: =G19 -> 175.59979 | I19: X | J19: From Historical figures.
A20: AP Days | B20: =365/(B29/(AVERAGE('ITC Limited Balance Sheet'!C20:D20))) -> 57.106418 | C20: =365/(C29/(AVERAGE('ITC Limited Balance Sheet'!B20:C20))) -> 63.341151 | D20: =C20 -> 63.341151 | E20: =D20 -> 63.341151 | F20: =E20 -> 63.341151 | G20: =F20 -> 63.341151 | H20: =G20 -> 63.341151 | I20: X | J20: From Historical figures.
I21: X
I22: X
I23: X
A24: 1.1. FINANCIAL STATEMENTS | I24: X
I25: X
A26: 1.1.A. INCOME STATEMENT | I26: X
I27: X
A28: Revenue | B28: ='ITC Limited Income Statement'!C13 -> 72917.34 | C28: ='ITC Limited Income Statement'!B13 -> 73608.84 | D28: =C28*(1+D9) -> 78761.459 | E28: =D28*(1+E9) -> 84274.761 | F28: =E28*(1+F9) -> 90173.994 | G28: =F28*(1+G9) -> 96486.174 | H28: =G28*(1+H9) -> 103240.21 | I28: X | J28: From Assumptions.
A29: (Less): Variable Costs | B29: ='ITC Limited Income Statement'!C14 -> 29005.77 | C29: ='ITC Limited Income Statement'!B14 -> 27247.21 | D29: =D10*D28 -> 29141.74 | E29: =E10*E28 -> 31181.662 | F29: =F10*F28 -> 33364.378 | G29: =G10*G28 -> 35699.884 | H29: =H10*H28 -> 38198.876 | I29: X | J29: From Assumptions.
A30: Contribution | B30: =B28-B29 -> 43911.57 | C30: =C28-C29 -> 46361.63 | D30: =D28-D29 -> 49619.719 | E30: =E28-E29 -> 53093.099 | F30: =F28-F29 -> 56809.616 | G30: =G28-G29 -> 60786.289 | H30: =H28-H29 -> 65041.33 | I30: X
A31: (Less): Fixed Costs | B31: ='ITC Limited Income Statement'!C16 -> 18075.16 | C31: ='ITC Limited Income Statement'!B16 -> 19195.83 | D31: =D28*D11 -> 21265.594 | E31: =E28*E11 -> 22754.185 | F31: =F28*F11 -> 24346.978 | G31: =G28*G11 -> 26051.267 | H31: =H28*H11 -> 27874.856 | I31: X | J31: From Assumptions.
A32: Operating Income (EBIT) | B32: =B30-B31 -> 25836.41 | C32: =C30-C31 -> 27165.8 | D32: =D30-D31 -> 28354.125 | E32: =E30-E31 -> 30338.914 | F32: =F30-F31 -> 32462.638 | G32: =G30-G31 -> 34735.023 | H32: =H30-H31 -> 37166.474 | I32: X
A33: (Less): Finance Costs | B33: ='ITC Limited Income Statement'!C18 -> 116.07 | C33: ='ITC Limited Income Statement'!B18 -> 38.39 | D33: =D172 -> 91.408333 | E33: =E172 -> 90.380876 | F33: =F172 -> 89.353419 | G33: =G172 -> 88.325962 | H33: =H172 -> 87.298506 | I33: X | J33: From Debt schedule.
A34: EBT | B34: =B32-B33 -> 25720.34 | C34: =C32-C33 -> 27127.41 | D34: =D32-D33 -> 28262.717 | E34: =E32-E33 -> 30248.533 | F34: =F32-F33 -> 32373.284 | G34: =G32-G33 -> 34646.697 | H34: =H32-H33 -> 37079.176 | I34: X
A35: (Less): Tax Expense | B35: ='ITC Limited Income Statement'!C20 -> 6438.4 | C35: ='ITC Limited Income Statement'!B20 -> 6388.52 | D35: =D12*D34 -> 8478.8151 | E35: =E12*E34 -> 9074.5599 | F35: =F12*F34 -> 9711.9853 | G35: =G12*G34 -> 10394.009 | H35: =H12*H34 -> 11123.753 | I35: X | J35: From Assumptions.
A36: EAT before Extraordinary items | B36: =B34-B35 -> 19281.94 | C36: =C34-C35 -> 20738.89 | D36: =D34-D35 -> 19783.902 | E36: =E34-E35 -> 21173.973 | F36: =F34-F35 -> 22661.299 | G36: =G34-G35 -> 24252.688 | H36: =H34-H35 -> 25955.423 | I36: X
A37: Less: Extraordinary Items | B37: =-SUM('ITC Limited Income Statement'!C22:C23) -> 236.02 | C37: =-SUM('ITC Limited Income Statement'!B22:B23) -> 264.97 | D37: =D36*D13 -> 395.67804 | E37: =E36*E13 -> 423.47946 | F37: =F36*F13 -> 453.22598 | G37: =G36*G13 -> 485.05375 | H37: =H36*H13 -> 519.10846 | I37: X | J37: From Assumptions.
A38: EAT After Extraordinary Items | B38: =B36-B37 -> 19045.92 | C38: =C36-C37 -> 20473.92 | D38: =D36-D37 -> 19388.224 | E38: =E36-E37 -> 20750.494 | F38: =F36-F37 -> 22208.073 | G38: =G36-G37 -> 23767.634 | H38: =H36-H37 -> 25436.314 | I38: X
I39: X
I40: X
...

Sheet 1. Part 1B - DCF
A1: Discounted Cash Flow | B1: ='1. Part 1A - 3FS'!B2 -> Historical | C1: ='1. Part 1A - 3FS'!C2 -> Historical | D1: ='1. Part 1A - 3FS'!D2 -> Projected | E1: ='1. Part 1A - 3FS'!E2 -> Projected | F1: ='1. Part 1A - 3FS'!F2 -> Projected | G1: ='1. Part 1A - 3FS'!G2 -> Projected | H1: ='1. Part 1A - 3FS'!H2 -> Projected | J1: ='1. Part 1A - 3FS'!J2 -> Notes
A2: ='1. Part 1A - 3FS'!A3 -> ITC Ltd. | B2: ='1. Part 1A - 3FS'!B3 -> 2023 | C2: =B2+1 -> 2024 | D2: =C2+1 -> 2025 | E2: =D2+1 -> 2026 | F2: =E2+1 -> 2027 | G2: =F2+1 -> 2028 | H2: =G2+1 -> 2029
A3: ='1. Part 1A - 3FS'!A4 -> (₹) in Crores | I3: X
I4: X
A5: 1.5. Compute Weighted Average Cost of Capital(WACC) | I5: X
I6: X
A7: Computation of Free Cash Flow to Firm (FCFF) | I7: X
I8: X
A9: EBIT * (1-Tax Rate) | B9: ='1. Part 1A - 3FS'!B32*(1-'1. Part 1A - 3FS'!B12) -> 19368.955 | C9: ='1. Part 1A - 3FS'!C32*(1-'1. Part 1A - 3FS'!C12) -> 20768.239 | D9: ='1. Part 1A - 3FS'!D32*(1-'1. Part 1A - 3FS'!D12) -> 19847.888 | E9: ='1. Part 1A - 3FS'!E32*(1-'1. Part 1A - 3FS'!E12) -> 21237.24 | F9: ='1. Part 1A - 3FS'!F32*(1-'1. Part 1A - 3FS'!F12) -> 22723.847 | G9: ='1. Part 1A - 3FS'!G32*(1-'1. Part 1A - 3FS'!G12) -> 24314.516 | H9: ='1. Part 1A - 3FS'!H32*(1-'1. Part 1A - 3FS'!H12) -> 26016.532 | I9: X | J9: From the Income Statement.
A10: Add: | I10: X
A11: Non-Cash Expenses | B11: =-SUM('1. Part 1A - 3FS'!B108:B110) -> 5239.07 | C11: =-SUM('1. Part 1A - 3FS'!C108:C110) -> 3476.24 | D11: =-SUM('1. Part 1A - 3FS'!D108:D110) -> 4740.1829 | E11: =-SUM('1. Part 1A - 3FS'!E108:E110) -> 5071.9957 | F11: =-SUM('1. Part 1A - 3FS'!F108:F110) -> 5427.0354 | G11: =-SUM('1. Part 1A - 3FS'!G108:G110) -> 5806.9279 | H11: =-SUM('1. Part 1A - 3FS'!H108:H110) -> 6213.4128 | I11: X | J11: From the Cash Flow Statement.
A12: Less: | I12: X
A13: CAPEX | B13: ='1. Part 1A - 3FS'!B156 -> 3900.79 | C13: ='1. Part 1A - 3FS'!C156 -> 1685.25 | D13: ='1. Part 1A - 3FS'!D156 -> 2356.0634 | E13: ='1. Part 1A - 3FS'!E156 -> 2535.9978 | F13: ='1. Part 1A - 3FS'!F156 -> 2713.5177 | G13: ='1. Part 1A - 3FS'!G156 -> 2903.4639 | H13: ='1. Part 1A - 3FS'!H156 -> 3106.7064 | I13: X | J13: From the PPE schedule.
A14: Net Increase/(Decrease) in Working Capital | B14: =('1. Part 1A - 3FS'!B58-'1. Part 1A - 3FS'!B88)-('ITC Limited Balance Sheet'!D41-'ITC Limited Balance Sheet'!D23) -> 4642.47 | C14: =('1. Part 1A - 3FS'!C58-'1. Part 1A - 3FS'!C88)-('1. Part 1A - 3FS'!B58-'1. Part 1A - 3FS'!B88) -> 663.93 | D14: =('1. Part 1A - 3FS'!D58-'1. Part 1A - 3FS'!D88)-('1. Part 1A - 3FS'!C58-'1. Part 1A - 3FS'!C88) -> 21688.964 | E14: =('1. Part 1A - 3FS'!E58-'1. Part 1A - 3FS'!E88)-('1. Part 1A - 3FS'!D58-'1. Part 1A - 3FS'!D88) -> 23253.638 | F14: =('1. Part 1A - 3FS'!F58-'1. Part 1A - 3FS'!F88)-('1. Part 1A - 3FS'!E58-'1. Part 1A - 3FS'!E88) -> 24888.737 | G14: =('1. Part 1A - 3FS'!G58-'1. Part 1A - 3FS'!G88)-('1. Part 1A - 3FS'!F58-'1. Part 1A - 3FS'!F88) -> 26638.244 | H14: =('1. Part 1A - 3FS'!H58-'1. Part 1A - 3FS'!H88)-('1. Part 1A - 3FS'!G58-'1. Part 1A - 3FS'!G88) -> 28510.167 | I14: X | J14: From the Balance Sheet.
A15: Free Cash Flow to Firm (FCFF) | B15: =B9+B11-B13-B14 -> 16064.765 | C15: =C9+C11-C13-C14 -> 21895.299 | D15: =D9+D11-D13-D14 -> 543.04287 | E15: =E9+E11-E13-E14 -> 519.60008 | F15: =F9+F11-F13-F14 -> 548.62738 | G15: =G9+G11-G13-G14 -> 579.73593 | H15: =H9+H11-H13-H14 -> 613.07141 | I15: X
I16: X
I17: X
I18: X
A19: Computation of Free Cash Flow to Equity (FCFE) | I19: X
I20: X
A21: Profit After Tax (PAT) | B21: ='1. Part 1A - 3FS'!B38 -> 19045.92 | C21: ='1. Part 1A - 3FS'!C38 -> 20473.92 | D21: ='1. Part 1A - 3FS'!D38 -> 19388.224 | E21: ='1. Part 1A - 3FS'!E38 -> 20750.494 | F21: ='1. Part 1A - 3FS'!F38 -> 22208.073 | G21: ='1. Part 1A - 3FS'!G38 -> 23767.634 | H21: ='1. Part 1A - 3FS'!H38 -> 25436.314 | I21: X | J21: From the Income Statement.
A22: =A10 -> Add: | I22: X
A23: =A11 -> Non-Cash Expenses | B23: =B11 -> 5239.07 | C23: =C11 -> 3476.24 | D23: =D11 -> 4740.1829 | E23: =E11 -> 5071.9957 | F23: =F11 -> 5427.0354 | G23: =G11 -> 5806.9279 | H23: =H11 -> 6213.4128 | I23: X | J23: From FCFF computation.
A24: =A12 -> Less: | I24: X
A25: =A13 -> CAPEX | B25: =B13 -> 3900.79 | C25: =C13 -> 1685.25 | D25: =D13 -> 2356.0634 | E25: =E13 -> 2535.9978 | F25: =F13 -> 2713.5177 | G25: =G13 -> 2903.4639 | H25: =H13 -> 3106.7064 | I25: X | J25: From FCFF computation.
A26: =A14 -> Net Increase/(Decrease) in Working Capital | B26: =B14 -> 4642.47 | C26: =C14 -> 663.93 | D26: =D14 -> 21688.964 | E26: =E14 -> 23253.638 | F26: =F14 -> 24888.737 | G26: =G14 -> 26638.244 | H26: =H14 -> 28510.167 | I26: X | J26: From FCFF computation.
A27: Net Increase/(Decrease) in Debt | B27: ='1. Part 1A - 3FS'!B164-'ITC Limited Balance Sheet'!D14 -> 294.01 | C27: ='1. Part 1A - 3FS'!C164-'1. Part 1A - 3FS'!B164 -> 613.65 | D27: ='1. Part 1A - 3FS'!D164-'1. Part 1A - 3FS'!C164 -> -32.854 | E27: ='1. Part 1A - 3FS'!E164-'1. Part 1A - 3FS'!D164 -> -32.854 | F27: ='1. Part 1A - 3FS'!F164-'1. Part 1A - 3FS'!E164 -> -32.854 | G27: ='1. Part 1A - 3FS'!G164-'1. Part 1A - 3FS'!F164 -> -32.854 | H27: ='1. Part 1A - 3FS'!H164-'1. Part 1A - 3FS'!G164 -> -32.854 | I27: X | J27: From the Debt schedule.
A28: Free Cash Flow to Equity (FCFE) | B28: =B21+B23-B25-B26-B27 -> 15447.72 | C28: =C21+C23-C25-C26-C27 -> 20987.33 | D28: =D21+D23-D25-D26-D27 -> 116.233 | E28: =E21+E23-E25-E26-E27 -> 65.708 | F28: =F21+F23-F25-F26-F27 -> 65.708 | G28: =G21+G23-G25-G26-G27 -> 65.708 | H28: =H21+H23-H25-H26-H27 -> 65.708 | I28: X
I29: X
I30: X
I31: X
A32: Computation of Weightage of Debt and Equity | I32: X
I33: X
A34: Debt | B34: ='1. Part 1A - 3FS'!B164 -> 2342.08 | C34: ='1. Part 1A - 3FS'!C164 -> 2955.73 | D34: ='1. Part 1A - 3FS'!D164 -> 2922.876 | E34: ='1. Part 1A - 3FS'!E164 -> 2890.022 | F34: ='1. Part 1A - 3FS'!F164 -> 2857.168 | G34: ='1. Part 1A - 3FS'!G164 -> 2824.314 | H34: ='1. Part 1A - 3FS'!H164 -> 2791.46 | I34: X | J34: From the Debt schedule.
A35: Equity | B35: ='1. Part 1A - 3FS'!B75 -> 1242.8 | C35: ='1. Part 1A - 3FS'!C75 -> 1248.47 | D35: ='1. Part 1A - 3FS'!D75 -> 1248.47 | E35: ='1. Part 1A - 3FS'!E75 -> 1248.47 | F35: ='1. Part 1A - 3FS'!F75 -> 1248.47 | G35: ='1. Part 1A - 3FS'!G75 -> 1248.47 | H35: ='1. Part 1A - 3FS'!H75 -> 1248.47 | I35: X | J35: From the Balance Sheet.
A36: Total Firm Value | B36: =B34+B35 -> 3584.88 | C36: =C34+C35 -> 4204.2 | D36: =D34+D35 -> 4171.346 | E36: =E34+E35 -> 4138.492 | F36: =F34+F35 -> 4105.638 | G36: =G34+G35 -> 4072.784 | H36: =H34+H35 -> 4039.93 | I36: X
I37: X
A38: Weightage of Debt (Wd) | B38: =B34/B$36 -> 0.65332173 | C38: =C34/C$36 -> 0.7030422 | D38: =D34/D$36 -> 0.70070332 | E38: =E34/E$36 -> 0.69832731 | F38: =F34/F$36 -> 0.69591328 | G38: =G34/G$36 -> 0.6934603 | H38: =H34/H$36 -> 0.69096742 | I38: X
A39: Weightage of Equity (We) | B39: =B35/B$36 -> 0.34667827 | C39: =C35/C$36 -> 0.2969578 | D39: =D35/D$36 -> 0.29929668 | E39: =E35/E$36 -> 0.30167269 | F39: =F35/F$36 -> 0.30408672 | G39: =G35/G$36 -> 0.3065397 | H39: =H35/H$36 -> 0.30903258 | I39: X
I40: X
...

Sheet ITC Limited Income Statement
A1: ITC Consolidated Profit and Loss Account
A2: Consolidated Profit & Loss account | B2: in Rs. Cr.
B3: 45352 | C3: 44986 | D3: 44621 | E3: 44256 | F3: 43891 | G3: 43525 | H3: 43160 | I3: 42795 | J3: 42430 | K3: 42064
B5: 12 mths | C5: 12 mths | D5: 12 mths | E5: 12 mths | F5: 12 mths | G5: 12 mths | H5: 12 mths | I5: 12 mths | J5: 12 mths | K5: 12 mths
A6: INCOME
A7: Revenue From Operations [Gross] | B7: 76274.98 | C7: 75826.58 | D7: 64618.23 | E7: 52835.15 | F7: 50968.5 | G7: 49348.43 | H7: 47362.51 | I7: 58287.95 | J7: 54673.17 | K7: 52759.08
A8: Less: Excise/Service Tax/Other Levies | B8: 5959.49 | C8: 5581.36 | D8: 4536.87 | E8: 3882.34 | F8: 1989.42 | G8: 1509.43 | H8: 4239.61 | I8: 15927.91 | J8: 15868.98 | K8: 14325.77
A9: Net Revenue | B9: =B7-B8 -> 70315.49 | C9: =C7-C8 -> 70245.22 | D9: =D7-D8 -> 60081.36 | E9: =E7-E8 -> 48952.81 | F9: =F7-F8 -> 48979.08 | G9: =G7-G8 -> 47839 | H9: =H7-H8 -> 43122.9 | I9: =I7-I8 -> 42360.04 | ... K9: =K7-K8 -> 38433.31
A10: Other Operating Revenues | B10: 565.51 | C10: 691.63 | D10: 586.73 | E10: 319.97 | F10: 424.97 | G10: 513.68 | H10: 326.04 | I10: 416.57 | J10: 387.91 | K10: 401.5
A11: Total Operating Revenues | B11: =B9+B10 -> 70881 | C11: =C9+C10 -> 70936.85 | D11: =D9+D10 -> 60668.09 | E11: =E9+E10 -> 49272.78 | F11: =F9+F10 -> 49404.05 | G11: =G9+G10 -> 48352.68 | H11: =H9+H10 -> 43448.94 | I11: =I9+I10 -> 42776.61 | ... K11: =K9+K10 -> 38834.81
A12: Other Income | B12: 2727.84 | C12: 1980.49 | D12: 1836.35 | E12: 2632.56 | F12: 2597.89 | G12: 2173.79 | H12: 1831.86 | I12: 1761.53 | J12: 1530.8 | K12: 1256.51
A13: Total Revenue | B13: =B11+B12 -> 73608.84 | C13: =C11+C12 -> 72917.34 | D13: =D11+D12 -> 62504.44 | E13: =E11+E12 -> 51905.34 | F13: =F11+F12 -> 52001.94 | G13: =G11+G12 -> 50526.47 | H13: =H11+H12 -> 45280.8 | I13: =I11+I12 -> 44538.14 | ... K13: =K11+K12 -> 40091.32 | L13: Revenue Growth Rate (%) | M13: =(B13-C13)/C13 -> 0.009483341 | N13: =(C13-D13)/D13 -> 0.16659457 | O13: =(D13-E13)/E13 -> 0.20420057 | P13: =(E13-F13)/F13 -> -0.001857623 | Q13: =(F13-G13)/G13 -> 0.029201921 | R13: =(G13-H13)/H13 -> 0.11584756 | S13: =(H13-I13)/I13 -> 0.016674697 | T13: =(I13-J13)/J13 -> 0.093687827 | U13: =(J13-K13)/K13 -> 0.015753535
A14: Less: Variable Costs | B14: 27247.21 | C14: 29005.77 | D14: 26385.07 | E14: 20131.44 | F14: 17345.47 | G14: 17420.33 | H14: 15855.48 | I14: 16049.16 | J14: 13568.5 | K14: 14772.18 | L14: Variable Cost % of Sales | M14: =B14/B13 -> 0.3701622 | N14: =C14/C13 -> 0.39778974 | O14: =D14/D13 -> 0.42213113 | P14: =E14/E13 -> 0.38784911 | Q14: =F14/F13 -> 0.33355429 | R14: =G14/G13 -> 0.34477631 | S14: =H14/H13 -> 0.35015901 | T14: =I14/I13 -> 0.36034644 | U14: =J14/J13 -> 0.33319091
A15: Contribution | B15: =B13-B14 -> 46361.63 | C15: =C13-C14 -> 43911.57 | D15: =D13-D14 -> 36119.37 | E15: =E13-E14 -> 31773.9 | F15: =F13-F14 -> 34656.47 | G15: =G13-G14 -> 33106.14 | H15: =H13-H14 -> 29425.32 | I15: =I13-I14 -> 28488.98 | ... K15: =K13-K14 -> 25319.14
A16: Less: Fixed Costs | B16: 19195.83 | C16: 18075.16 | D16: 15357.02 | E16: 13784.23 | F16: 14443.33 | G16: 13922.6 | H16: 12346.78 | I16: 12444.33 | J16: 12250.15 | K16: 10888.97 | L16: Fixed Cost % of Sales | M16: =C16/C13 -> 0.24788562 | N16: =D16/D13 -> 0.24569487 | O16: =E16/E13 -> 0.26556478 | P16: =F16/F13 -> 0.27774598 | Q16: =G16/G13 -> 0.27555062 | R16: =H16/H13 -> 0.27267142 | S16: =I16/I13 -> 0.27940839 | T16: =J16/J13 -> 0.30081723 | U16: =K16/K13 -> 0.27160418
A17: EBIT | B17: =B15-B16 -> 27165.8 | C17: =C15-C16 -> 25836.41 | D17: =D15-D16 -> 20762.35 | E17: =E15-E16 -> 17989.67 | F17: =F15-F16 -> 20213.14 | G17: =G15-G16 -> 19183.54 | H17: =H15-H16 -> 17078.54 | I17: =I15-I16 -> 16044.65 | ... K17: =K15-K16 -> 14430.17
A18: Less: Interest Cost | B18: 38.39 | C18: 116.07 | D18: 39.36 | E18: 44.58 | F18: -77.43 | G18: 45.42 | H18: 502.81 | I18: 24.3 | J18: 53.6 | K18: 68.12
A19: EBT | B19: =B17-B18 -> 27127.41 | C19: =C17-C18 -> 25720.34 | D19: =D17-D18 -> 20722.99 | E19: =E17-E18 -> 17945.09 | F19: =F17-F18 -> 20290.57 | G19: =G17-G18 -> 19138.12 | H19: =H17-H18 -> 16575.73 | I19: =I17-I18 -> 16020.35 | ... K19: =K17-K18 -> 14362.05
A20: Less: Tax Expenses | B20: 6388.52 | C20: 6438.4 | D20: 5237.34 | E20: 4555.29 | F20: 4441.79 | G20: 6313.92 | H20: 5916.43 | I20: 5549.09 | J20: 5358.21 | K20: 4596.42 | L20: Tax Expense % of EBT | M20: =C20/C19 -> 0.25032328 | N20: =D20/D19 -> 0.2527309 | O20: =E20/E19 -> 0.25384604 | P20: =F20/F19 -> 0.21890908 | Q20: =G20/G19 -> 0.32991328 | R20: =H20/H19 -> 0.3569333 | S20: =I20/I19 -> 0.34637758 | T20: =J20/J19 -> 0.36080643 | U20: =K20/K19 -> 0.32003927
A21: EAT Before Extraordinary Items | B21: =B19-B20 -> 20738.89 | C21: =C19-C20 -> 19281.94 | D21: =D19-D20 -> 15485.65 | E21: =E19-E20 -> 13389.8 | F21: =F19-F20 -> 15848.78 | G21: =G19-G20 -> 12824.2 | H21: =H19-H20 -> 10659.3 | I21: =I19-I20 -> 10471.26 | ... K21: =K19-K20 -> 9765.63
A22: Minority Interest | B22: -292.58 | C22: -285.06 | D22: -260.47 | E22: -221.69 | F22: -286.55 | G22: -243.57 | H22: -221.48 | I22: -187.79 | J22: -156.41 | K22: -115.35
A23: Share Of Profit/Loss Of Associates | B23: 27.61 | C23: 49.04 | D23: 17.48 | E23: -6.92 | F23: 8.22 | G23: 11.7 | H23: 7.58 | I23: 5.97 | J23: 8.42 | K23: 12.89
A24: Consolidated EAT After MI And Associates | B24: =SUM(B21:B23) -> 20473.92 | C24: =SUM(C21:C23) -> 19045.92 | D24: =SUM(D21:D23) -> 15242.66 | E24: =SUM(E21:E23) -> 13161.19 | F24: =SUM(F21:F23) -> 15570.45 | G24: =SUM(G21:G23) -> 12592.33 | H24: =SUM(H21:H23) -> 10445.4 | I24: =SUM(I21:I23) -> 10289.44 | ... K24: =SUM(K21:K23) -> 9663.17 | L24: Extraordinary Items as % of EAT before Extraordinary items | M24: =-SUM(C22:C23)/C21 -> 0.01224047 | N24: =-SUM(D22:D23)/D21 -> 0.015691301 | O24: =-SUM(E22:E23)/E21 -> 0.017073444 | P24: =-SUM(F22:F23)/F21 -> 0.017561604 | Q24: =-SUM(G22:G23)/G21 -> 0.01808066 | R24: =-SUM(H22:H23)/H21 -> 0.020066984 | S24: =-SUM(I22:I23)/I21 -> 0.017363717 | T24: =-SUM(J22:J23)/J21 -> 0.015590301 | U24: =-SUM(K22:K23)/K21 -> 0.010491899
A25: OTHER ADDITIONAL INFORMATION
A26: EARNINGS PER SHARE
A27: Basic EPS (Rs.) | B27: 16 | C27: 16 | D27: 12 | E27: 11 | F27: 12 | G27: 10 | H27: 9 | I27: 9 | J27: 8 | K27: 12
A28: Diluted EPS (Rs.) | B28: 16 | C28: 15 | D28: 12 | E28: 11 | F28: 12 | G28: 10 | H28: 9 | I28: 8 | J28: 8 | K28: 12
A29: DIVIDEND AND DIVIDEND PERCENTAGE
A30: Equity Share Dividend | B30: 8388.91 | C30: 7448.41 | D30: 6469.48 | E30: 6152.68 | F30: 7048.71 | G30: 6285.21 | H30: 5770.01 | I30: 6840.12 | J30: 5009.7 | K30: 5009.7
A31: Tax On Dividend | B31: 0 | C31: 0 | D31: 0 | E31: 0 | F31: 1407.44 | G31: 1213.6 | H31: 1136.83 | I31: 1338.95 | J31: 992.74 | K31: 1051.76

Sheet ITC Limited Balance Sheet
A1: ITC Consolidated Balance Sheet
A2: Consolidated Balance Sheet | B2: in Rs. Cr.
B3: 45352 | C3: 44986 | D3: 44621 | E3: 44256 | F3: 43891 | G3: 43525 | H3: 43160 | I3: 42795 | J3: 42430 | K3: 42064
B4: 12 mths | C4: 12 mths | D4: 12 mths | E4: 12 mths | F4: 12 mths | G4: 12 mths | H4: 12 mths | I4: 12 mths | J4: 12 mths | K4: 12 mths
A5: EQUITIES AND LIABILITIES
A6: SHAREHOLDER'S FUNDS
A7: Total Share Capital | B7: 1248.47 | C7: 1242.8 | D7: 1232.33 | E7: 1230.88 | F7: 1229.22 | G7: 1225.86 | H7: 1220.43 | I7: 1214.74 | J7: 804.72 | K7: 801.55
A8: Total Reserves and Surplus | B8: 73258.53 | C8: 67912.46 | D8: 61223.24 | E8: 59116.46 | F8: 64044.04 | G8: 57915.01 | H8: 51289.69 | I8: 45198.19 | J8: 41874.8 | K8: 30933.94
A9: Total Shareholders Funds | B9: =B7+B8 -> 74507 | C9: =C7+C8 -> 69155.26 | D9: =D7+D8 -> 62455.57 | E9: =E7+E8 -> 60347.34 | F9: =F7+F8 -> 65273.26 | G9: =G7+G8 -> 59140.87 | H9: =H7+H8 -> 52510.12 | I9: =I7+I8 -> 46412.93 | ... K9: =K7+K8 -> 31735.49
A10: Minority Interest | B10: 382.97 | C10: 383.53 | D10: 366.3 | E10: 346.81 | F10: 377.47 | G10: 343.47 | H10: 334.47 | I10: 294.74 | J10: 260.9 | K10: 225.11
A12: NON-CURRENT LIABILITIES
A13: Other Long Term Liabilities | B13: 1.76 | C13: 3.49 | D13: 4.85 | E13: 5.58 | F13: 5.9 | G13: 8.15 | H13: 11.5 | I13: 18.4 | J13: 26.66 | K13: 60.68
A14: Long Term Borrowings | B14: 2955.73 | C14: 2342.08 | D14: 2048.07 | E14: 2242.39 | F14: 1975.27 | G14: 2131.98 | H14: 2033 | I14: 1937.77 | J14: 1930.92 | K14: 1685.44
A15: Long Term Provisions | B15: 288.3 | C15: 259.21 | D15: 221.05 | E15: 187.5 | F15: 175.37 | G15: 161.95 | H15: 149.63 | I15: 158.42 | J15: 135.42 | K15: 124.16
A16: Total Non-Current Liabilities | B16: =SUM(B13:B15) -> 3245.79 | C16: =SUM(C13:C15) -> 2604.78 | D16: =SUM(D13:D15) -> 2273.97 | E16: =SUM(E13:E15) -> 2435.47 | F16: =SUM(F13:F15) -> 2156.54 | G16: =SUM(G13:G15) -> 2302.08 | H16: =SUM(H13:H15) -> 2194.13 | I16: =SUM(I13:I15) -> 2114.59 | ... K16: =SUM(K13:K15) -> 1870.28
A18: CURRENT LIABILITIES
A19: Short Term Borrowings | B19: 9.52 | C19: 35.32 | D19: 0.74 | E19: 3.88 | F19: 1.42 | G19: 1.86 | H19: 17.35 | I19: 19.11 | J19: 43.95 | K19: 195.39
A20: Trade Payables | B20: 4797.83 | C20: 4658.99 | D20: 4417.26 | E20: 4318.73 | F20: 3629.83 | G20: 3509.58 | H20: 3496.18 | I20: 2659.33 | J20: 2339.29 | K20: 2020.47
A21: Other Current Liabilities | B21: 8776.14 | C21: 8944.54 | D21: 7666.15 | E21: 6173.06 | F21: 5780.34 | G21: 6449.17 | H21: 5672.81 | I21: 4381.41 | J21: 4203.82 | K21: 3782.04
A22: Short Term Provisions | B22: 106.91 | C22: 100.56 | D22: 79.56 | E22: 194.01 | F22: 148.18 | G22: 51.38 | H22: 63.8 | I22: 61.16 | J22: 71.4 | K22: 6162.01
A23: Total Current Liabilities | B23: =SUM(B19:B22) -> 13690.4 | C23: =SUM(C19:C22) -> 13739.41 | D23: =SUM(D19:D22) -> 12163.71 | E23: =SUM(E19:E22) -> 10689.68 | F23: =SUM(F19:F22) -> 9559.77 | G23: =SUM(G19:G22) -> 10011.99 | H23: =SUM(H19:H22) -> 9250.14 | I23: =SUM(I19:I22) -> 7121.01 | ... K23: =SUM(K19:K22) -> 12159.91
A24: Total Capital And Liabilities | B24: =B9+B10+B16+B23 -> 91826.16 | C24: =C9+C10+C16+C23 -> 85882.98 | D24: =D9+D10+D16+D23 -> 77259.55 | E24: =E9+E10+E16+E23 -> 73819.3 | F24: =F9+F10+F16+F23 -> 77367.04 | G24: =G9+G10+G16+G23 -> 71798.41 | H24: =H9+H10+H16+H23 -> 64288.86 | I24: =I9+I10+I16+I23 -> 55943.27 | ... K24: =K9+K10+K16+K23 -> 45990.79
A26: ASSETS
A27: NON-CURRENT ASSETS
A28: Fixed Assets | B28: 29901.27 | C28: 28074.84 | D28: 26677.4 | E28: 26530.04 | F28: 24767.27 | G28: 23308.08 | H28: 21829.76 | I28: 19420.84 | J28: 17463.82 | K28: 17771.51
A29: Non-Current Investments | B29: 18169.6 | C29: 12182.16 | D29: 12576.73 | E29: 10024.54 | F29: 10715.02 | G29: 11695.99 | H29: 11483.79 | I29: 6693.99 | J29: 5125.81 | K29: 807.68
A30: Long Term Loans And Advances | B30: 4.05 | C30: 5.48 | D30: 6.61 | E30: 4.07 | F30: 5.27 | G30: 8.34 | H30: 9.69 | I30: 8.54 | J30: 12.96 | K30: 1565.47
A31: Other Non-Current Assets | B31: 2685.7 | C31: 5169.88 | D31: 3766.36 | E31: 2268.66 | F31: 2374.13 | G31: 5038.73 | H31: 4572 | I31: 3550.8 | J31: 4226.79 | K31: 271.78
A32: Total Non-Current Assets | B32: =SUM(B28:B31) -> 50760.62 | C32: =SUM(C28:C31) -> 45432.36 | D32: =SUM(D28:D31) -> 43027.1 | E32: =SUM(E28:E31) -> 38827.31 | F32: =SUM(F28:F31) -> 37861.69 | G32: =SUM(G28:G31) -> 40051.14 | H32: =SUM(H28:H31) -> 37895.24 | I32: =SUM(I28:I31) -> 29674.17 | ... K32: =SUM(K28:K31) -> 20416.44
A34: CURRENT ASSETS
A35: Current Investments | B35: 12944.42 | C35: 17232.86 | D35: 12264.28 | E35: 14846.33 | F35: 17948.33 | G35: 13347.5 | H35: 10569.07 | I35: 10887.39 | J35: 6621.78 | K35: 6135.09 | L35: Current Investments Growth Rate (%) | M35: =(B35-C35)/C35 -> -0.24885248 | N35: =(C35-D35)/D35 -> 0.40512611 | O35: =(D35-E35)/E35 -> -0.1739184 | P35: =(E35-F35)/F35 -> -0.17282945 | Q35: =(F35-G35)/G35 -> 0.34469601 | R35: =(G35-H35)/H35 -> 0.26288311 | S35: =(H35-I35)/I35 -> -0.029237494 | T35: =(I35-J35)/J35 -> 0.64417876 | U35: =(J35-K35)/K35 -> 0.07932891
A36: Inventories | B36: 14302.88 | C36: 11914.13 | D36: 10973.59 | E36: 10507.22 | F36: 8965.53 | G36: 7943.97 | H36: 7584.53 | I36: 8186.15 | J36: 9062.1 | K36: 8586.87
A37: Trade Receivables | B37: 4025.82 | C37: 2956.17 | D37: 2461.9 | E37: 2501.7 | F37: 2562.48 | G37: 4035.28 | H37: 2682.29 | I37: 2474.29 | J37: 1917.18 | K37: 1982.07
A38: Cash And Cash Equivalents | B38: 7217.68 | C38: 4880.19 | D38: 4654.42 | E38: 4659.02 | F38: 7277.34 | G38: 4152.03 | H38: 2899.6 | I38: 2967.4 | J38: 6063.3 | K38: 7896.22
A39: Short Term Loans And Advances | B39: 9.81 | C39: 7.12 | D39: 6.77 | E39: 3.47 | F39: 6.33 | G39: 6.75 | H39: 5.84 | I39: 6.78 | J39: 8.07 | K39: 568.67
A40: Other Current Assets | B40: 2564.93 | C40: 3460.15 | D40: 3871.49 | E40: 2474.25 | F40: 2745.34 | G40: 2261.74 | H40: 2652.29 | I40: 1747.09 | J40: 1190.07 | K40: 405.43
A41: Total Current Assets | B41: =SUM(B35:B40) -> 41065.54 | C41: =SUM(C35:C40) -> 40450.62 | D41: =SUM(D35:D40) -> 34232.45 | E41: =SUM(E35:E40) -> 34991.99 | F41: =SUM(F35:F40) -> 39505.35 | G41: =SUM(G35:G40) -> 31747.27 | H41: =SUM(H35:H40) -> 26393.62 | I41: =SUM(I35:I40) -> 26269.1 | ... K41: =SUM(K35:K40) -> 25574.35
A42: Total Assets | B42: =SUM(B32,B41) -> 91826.16 | C42: =SUM(C32,C41) -> 85882.98 | D42: =SUM(D32,D41) -> 77259.55 | E42: =SUM(E32,E41) -> 73819.3 | F42: =SUM(F32,F41) -> 77367.04 | G42: =SUM(G32,G41) -> 71798.41 | H42: =SUM(H32,H41) -> 64288.86 | I42: =SUM(I32,I41) -> 55943.27 | ... K42: =SUM(K32,K41) -> 45990.79
B43: =B24-B42 -> 0 | C43: =C24-C42 -> 0 | D43: =D24-D42 -> 0 | E43: =E24-E42 -> 0 | F43: =F24-F42 -> 0 | G43: =G24-G42 -> 0 | H43: =H24-H42 -> 0 | I43: =I24-I42 -> 0 | ... K43: =K24-K42 -> 0
A45: OTHER ADDITIONAL INFORMATION
...

Sheet Part 2 - CAPM 2.1, 2.2 and 2.3
A1: Oil & Natural Gas Corporation Ltd. Last 5 Years Equity Share Price (NSE) (Stock Return - Rs) | E1: Nifty 500 Last 5 Years Equity Share Price (NSE) (Market Return - Rm) | I1: India 3-Month Bond Yield Historical Data (Investing.Com) (Risk Free Rate - Rf) | M1: Identification of the Dependent and Independent Variable - Referenced to Part 2 - CAPM 2.3 | Q1: 1) Independent Variable (IV): Market Return (NIFTY 500 Daily Return) - Daily Risk Free Rate (3 Month India Bond Yield).
A2: DATE (2.1) | B2: CLOSE (2.1) | C2: DAILY RETURNS (%) (2.2) | E2: DATE (2.1) | F2: CLOSE (2.1) | G2: DAILY RETURNS (%) (2.2) | I2: DATE (2.1) | J2: BOND YIELD ANNUALIZED (%) (2.1) | K2: BOND YIELD DAILY (%) (2.2) | M2: DATE | N2: RM-RF (%) (IV) (2.3) | O2: RS-RF (%) (DV) (2.3) | Q2: 2) Dependent Variable (DV): Daily Return of Stock (ONGC) - Daily Risk Free Rate (3 Month India Bond Yield).
A3: 43557 | B3: 157.5 | C3: 0 | E3: 43557 | F3: 9720.8 | G3: 0 | I3: 43557 | J3: 0.0618 | K3: =((1+J3)^(1/365))-1 -> 0.00016430276 | M3: 43557 | N3: =G3-K3 -> -0.00016430276 | O3: ='Part 2 - CAPM 2.1, 2.2 and 2.3'!C3-'Part 2 - CAPM 2.1, 2.2 and 2.3'!K3 -> -0.00016430276
A4: 43558 | B4: 155.45 | C4: =(B4-B3)/B3 -> -0.013015873 | E4: 43558 | F4: 9658.4 | G4: =(F4-F3)/F3 -> -0.0064192248 | I4: 43558 | J4: 0.0622 | K4: =((1+J4)^(1/365))-1 -> 0.00016533484 | M4: 43558 | N4: =G4-K4 -> -0.0065845596 | O4: ='Part 2 - CAPM 2.1, 2.2 and 2.3'!C4-'Part 2 - CAPM 2.1, 2.2 and 2.3'!K4 -> -0.013181208
A5: 43559 | B5: 155.25 | C5: =(B5-B4)/B4 -> -0.0012865873 | E5: 43559 | F5: 9626.65 | G5: =(F5-F4)/F4 -> -0.003287294 | I5: 43559 | J5: 0.0622 | K5: =((1+J5)^(1/365))-1 -> 0.00016533484 | M5: 43559 | N5: =G5-K5 -> -0.0034526288 | O5: ='Part 2 - CAPM 2.1, 2.2 and 2.3'!C5-'Part 2 - CAPM 2.1, 2.2 and 2.3'!K5 -> -0.0014519222
A6: 43560 | B6: 156.55 | C6: =(B6-B5)/B5 -> 0.008373591 | E6: 43560 | F6: 9684.95 | G6: =(F6-F5)/F5 -> 0.0060561047 | I6: 43560 | J6: 0.0621 | K6: =((1+J6)^(1/365))-1 -> 0.00016507686 | M6: 43560 | N6: =G6-K6 -> 0.0058910278 | O6: ='Part 2 - CAPM 2.1, 2.2 and 2.3'!C6-'Part 2 - CAPM 2.1, 2.2 and 2.3'!K6 -> 0.0082085141
A7: 43563 | B7: 158.1 | C7: =(B7-B6)/B6 -> 0.0099009901 | E7: 43563 | F7: 9634.4 | G7: =(F7-F6)/F6 -> -0.0052194384 | I7: 43563 | J7: 0.062 | K7: =((1+J7)^(1/365))-1 -> 0.00016481885 | M7: 43563 | N7: =G7-K7 -> -0.0053842573 | O7: ='Part 2 - CAPM 2.1, 2.2 and 2.3'!C7-'Part 2 - CAPM 2.1, 2.2 and 2.3'!K7 -> 0.0097361712
A8: 43564 | B8: 157.55 | C8: =(B8-B7)/B7 -> -0.0034788109 | E8: 43564 | F8: 9677.75 | G8: =(F8-F7)/F7 -> 0.0044995018 | I8: 43564 | J8: 0.062 | K8: =((1+J8)^(1/365))-1 -> 0.00016481885 | M8: 43564 | N8: =G8-K8 -> 0.0043346829 | O8: ='Part 2 - CAPM 2.1, 2.2 and 2.3'!C8-'Part 2 - CAPM 2.1, 2.2 and 2.3'!K8 -> -0.0036436297
A9: 43565 | B9: 158 | C9: =(B9-B8)/B8 -> 0.0028562361 | E9: 43565 | F9: 9622.95 | G9: =(F9-F8)/F8 -> -0.0056624732 | I9: 43565 | J9: 0.0622 | K9: =((1+J9)^(1/365))-1 -> 0.00016533484 | M9: 43565 | N9: =G9-K9 -> -0.005827808 | O9: ='Part 2 - CAPM 2.1, 2.2 and 2.3'!C9-'Part 2 - CAPM 2.1, 2.2 and 2.3'!K9 -> 0.0026909013
A10: 43566 | B10: 158.6 | C10: =(B10-B9)/B9 -> 0.0037974684 | E10: 43566 | F10: 9634.55 | G10: =(F10-F9)/F9 -> 0.0012054516 | I10: 43566 | J10: 0.0632 | K10: =((1+J10)^(1/365))-1 -> 0.00016791335 | M10: 43566 | N10: =G10-K10 -> 0.0010375382 | O10: ='Part 2 - CAPM 2.1, 2.2 and 2.3'!C10-'Part 2 - CAPM 2.1, 2.2 and 2.3'!K10 -> 0.003629555
A11: 43567 | B11: 157.6 | C11: =(B11-B10)/B10 -> -0.0063051702 | E11: 43567 | F11: 9674.6 | G11: =(F11-F10)/F10 -> 0.0041569144 | I11: 43567 | J11: 0.0631 | K11: =((1+J11)^(1/365))-1 -> 0.00016765561 | M11: 43567 | N11: =G11-K11 -> 0.0039892588 | O11: ='Part 2 - CAPM 2.1, 2.2 and 2.3'!C11-'Part 2 - CAPM 2.1, 2.2 and 2.3'!K11 -> -0.0064728258
A12: 43570 | B12: 156.45 | C12: =(B12-B11)/B11 -> -0.0072969543 | E12: 43570 | F12: 9716.5 | G12: =(F12-F11)/F11 -> 0.0043309284 | I12: 43570 | J12: 0.0631 | K12: =((1+J12)^(1/365))-1 -> 0.00016765561 | M12: 43570 | N12: =G12-K12 -> 0.0041632728 | O12: ='Part 2 - CAPM 2.1, 2.2 and 2.3'!C12-'Part 2 - CAPM 2.1, 2.2 and 2.3'!K12 -> -0.0074646099
A13: 43571 | B13: 160.45 | C13: =(B13-B12)/B12 -> 0.025567274 | E13: 43571 | F13: 9781.4 | G13: =(F13-F12)/F12 -> 0.0066793599 | I13: 43571 | J13: 0.0634 | K13: =((1+J13)^(1/365))-1 -> 0.00016842876 | M13: 43571 | N13: =G13-K13 -> 0.0065109311 | O13: ='Part 2 - CAPM 2.1, 2.2 and 2.3'!C13-'Part 2 - CAPM 2.1, 2.2 and 2.3'!K13 -> 0.025398845
A14: 43573 | B14: 160.6 | C14: =(B14-B13)/B13 -> 0.00093487068 | E14: 43573 | F14: 9738.7 | G14: =(F14-F13)/F13 -> -0.0043654283 | I14: 43573 | J14: 0.0634 | K14: =((1+J14)^(1/365))-1 -> 0.00016842876 | M14: 43573 | N14: =G14-K14 -> -0.004533857 | O14: ='Part 2 - CAPM 2.1, 2.2 and 2.3'!C14-'Part 2 - CAPM 2.1, 2.2 and 2.3'!K14 -> 0.00076644191
A15: 43577 | B15: 157.9 | C15: =(B15-B14)/B14 -> -0.016811955 | E15: 43577 | F15: 9599.8 | G15: =(F15-F14)/F14 -> -0.014262684 | I15: 43577 | J15: 0.0635 | K15: =((1+J15)^(1/365))-1 -> 0.00016868643 | M15: 43577 | N15: =G15-K15 -> -0.01443137 | O15: ='Part 2 - CAPM 2.1, 2.2 and 2.3'!C15-'Part 2 - CAPM 2.1, 2.2 and 2.3'!K15 -> -0.016980642
... A1213: 45379 | B1213: 268.05 | C1213: =(B1213-B1212)/B1212 -> 0.024068768 | E1213: 45379 | F1213: 20255.15 | G1213: =(F1213-F1212)/F1212 -> 0.0083309272 | I1213: 45379 | J1213: 0.0702 | K1213: =((1+J1213)^(1/365))-1 -> 0.00018589549 | M1213: 45379 | N1213: =G1213-K1213 -> 0.0081450317 | O1213: ='Part 2 - CAPM 2.1, 2.2 and 2.3'!C1213-'Part 2 - CAPM 2.1, 2.2 and 2.3'!K1213 -> 0.023882872

Sheet Part 2 - CAPM - 2.4
A1: Regression run on ONGC Limited and NIFTY 500
A2: SUMMARY OUTPUT
A4: Regression Statistics
A5: Multiple R | B5: 0.49633432
A6: R Square | B6: 0.24634776
A7: Adjusted R Square | B7: 0.24572439
A8: Standard Error | B8: 0.021064257
A9: Observations | B9: 1211
A11: ANOVA
B12: df | C12: SS | D12: MS | E12: F | F12: Significance F
A13: Regression | B13: 1 | C13: 0.17534614 | D13: 0.17534614 | E13: 395.18815 | F13: 2.5920303e-76
A14: Residual | B14: 1209 | C14: 0.53643683 | D14: 0.00044370292
A15: Total | B15: 1210 | C15: 0.71178297
B17: Coefficients | C17: Standard Error | D17: t Stat | E17: P-value | F17: Lower 95% | G17: Upper 95% | H17: Lower 95.0% | I17: Upper 95.0%
A18: Intercept | B18: 5.3280234e-05 | C18: 0.00060593064 | D18: 0.087931242 | E18: 0.92994589 | F18: -0.0011355121 | G18: 0.0012420726 | H18: -0.0011355121 | I18: 0.0012420726
A19: RM-RF (%) (IV) (2.3) | B19: 1.0021993 | C19: 0.050414114 | D19: 19.87934 | E19: 2.5920303e-76 | F19: 0.90329043 | G19: 1.1011082 | H19: 0.90329043 | I19: 1.1011082

Sheet Part 2 - CAPM 2.5
A1: CAPM Model Generation | E1: India 3-Month Bond Yield Historical Data (Investing.Com) (Risk Free Rate - Rf) | I1: Beta from Regression (B) | J1: ='Part 2 - CAPM - 2.4'!B19 -> 1.0021993 | L1: CAPM Model Cost of Equity (Ke) = Rf + B*(Rm-Rf)+ARM NIFTY 500 Ke | M1: CAPM Model Cost of Equity (Ke) = Rf + B*(Rs-Rf)+ARM ONGC Ke | O1: 2.5. CAPM Equation (Ke) = Rf + B*(Rm-Rf)+ARm NIFTY 500 Ke
A2: DATE | B2: RM-RF (%) (IV) (2.3) | C2: RS-RF (%) (DV) (2.3) | E2: DATE (2.1) | F2: BOND YIELD ANNUALIZED (%) (2.1) | G2: BOND YIELD DAILY (%) (2.2) | I2: Beta from Formula (B) | J2: =SLOPE(C3:C1213,B3:B1213) -> 1.0021993 | O2: Ke | P2: Rf | Q2: B | R2: Rm-Rf | S2: Arm
A3: 43557 | B3: ='Part 2 - CAPM 2.1, 2.2 and 2.3'!N3 -> -0.00016430276 | C3: ='Part 2 - CAPM 2.1, 2.2 and 2.3'!O3 -> -0.00016430276 | E3: 43557 | F3: 0.0618 | G3: =((1+F3)^(1/365))-1 -> 0.00016430276 | L3: =G3+($J$1*(B3)) -> -3.613504e-07 | M3: =G3+($J$1*(C3)) -> -3.613504e-07 | O3: =P3+(Q3*(R3))+S3 -> -3.613504e-07 | P3: =G3 -> 0.00016430276 | Q3: =$J$1 -> 1.0021993 | R3: =B3 -> -0.00016430276 | S3: 0
A4: 43558 | B4: ='Part 2 - CAPM 2.1, 2.2 and 2.3'!N4 -> -0.0065845596 | C4: ='Part 2 - CAPM 2.1, 2.2 and 2.3'!O4 -> -0.013181208 | E4: 43558 | F4: 0.0622 | G4: =((1+F4)^(1/365))-1 -> 0.00016533484 | L4: =G4+($J$1*(B4)) -> -0.0064337062 | M4: =G4+($J$1*(C4)) -> -0.013044862 | O4: =P4+(Q4*(R4))+S4 -> -0.0064337062 | P4: =G4 -> 0.00016533484 | Q4: =$J$1 -> 1.0021993 | R4: =B4 -> -0.0065845596 | S4: 0
A5: 43559 | B5: ='Part 2 - CAPM 2.1, 2.2 and 2.3'!N5 -> -0.0034526288 | C5: ='Part 2 - CAPM 2.1, 2.2 and 2.3'!O5 -> -0.0014519222 | E5: 43559 | F5: 0.0622 | G5: =((1+F5)^(1/365))-1 -> 0.00016533484 | L5: =G5+($J$1*(B5)) -> -0.0032948873 | M5: =G5+($J$1*(C5)) -> -0.0012897805 | O5: =P5+(Q5*(R5))+S5 -> -0.0032948873 | P5: =G5 -> 0.00016533484 | Q5: =$J$1 -> 1.0021993 | R5: =B5 -> -0.0034526288 | S5: 0
A6: 43560 | B6: ='Part 2 - CAPM 2.1, 2.2 and 2.3'!N6 -> 0.0058910278 | C6: ='Part 2 - CAPM 2.1, 2.2 and 2.3'!O6 -> 0.0082085141 | E6: 43560 | F6: 0.0621 | G6: =((1+F6)^(1/365))-1 -> 0.00016507686 | L6: =G6+($J$1*(B6)) -> 0.0060690608 | M6: =G6+($J$1*(C6)) -> 0.0083916439 | O6: =P6+(Q6*(R6))+S6 -> 0.0060690608 | P6: =G6 -> 0.00016507686 | Q6: =$J$1 -> 1.0021993 | R6: =B6 -> 0.0058910278 | S6: 0
A7: 43563 | B7: ='Part 2 - CAPM 2.1, 2.2 and 2.3'!N7 -> -0.0053842573 | C7: ='Part 2 - CAPM 2.1, 2.2 and 2.3'!O7 -> 0.0097361712 | E7: 43563 | F7: 0.062 | G7: =((1+F7)^(1/365))-1 -> 0.00016481885 | L7: =G7+($J$1*(B7)) -> -0.00523128 | M7: =G7+($J$1*(C7)) -> 0.0099224028 | O7: =P7+(Q7*(R7))+S7 -> -0.00523128 | P7: =G7 -> 0.00016481885 | Q7: =$J$1 -> 1.0021993 | R7: =B7 -> -0.0053842573 | S7: 0
A8: 43564 | B8: ='Part 2 - CAPM 2.1, 2.2 and 2.3'!N8 -> 0.0043346829 | C8: ='Part 2 - CAPM 2.1, 2.2 and 2.3'!O8 -> -0.0036436297 | E8: 43564 | F8: 0.062 | G8: =((1+F8)^(1/365))-1 -> 0.00016481885 | L8: =G8+($J$1*(B8)) -> 0.004509035 | M8: =G8+($J$1*(C8)) -> -0.0034868243 | O8: =P8+(Q8*(R8))+S8 -> 0.004509035 | P8: =G8 -> 0.00016481885 | Q8: =$J$1 -> 1.0021993 | R8: =B8 -> 0.0043346829 | S8: 0
A9: 43565 | B9: ='Part 2 - CAPM 2.1, 2.2 and 2.3'!N9 -> -0.005827808 | C9: ='Part 2 - CAPM 2.1, 2.2 and 2.3'!O9 -> 0.0026909013 | E9: 43565 | F9: 0.0622 | G9: =((1+F9)^(1/365))-1 -> 0.00016533484 | L9: =G9+($J$1*(B9)) -> -0.0056752903 | M9: =G9+($J$1*(C9)) -> 0.0028621542 | O9: =P9+(Q9*(R9))+S9 -> -0.0056752903 | P9: =G9 -> 0.00016533484 | Q9: =$J$1 -> 1.0021993 | R9: =B9 -> -0.005827808 | S9: 0
A10: 43566 | B10: ='Part 2 - CAPM 2.1, 2.2 and 2.3'!N10 -> 0.0010375382 | C10: ='Part 2 - CAPM 2.1, 2.2 and 2.3'!O10 -> 0.003629555 | E10: 43566 | F10: 0.0632 | G10: =((1+F10)^(1/365))-1 -> 0.00016791335 | L10: =G10+($J$1*(B10)) -> 0.0012077334 | M10: =G10+($J$1*(C10)) -> 0.0038054508 | O10: =P10+(Q10*(R10))+S10 -> 0.0012077334 | P10: =G10 -> 0.00016791335 | Q10: =$J$1 -> 1.0021993 | R10: =B10 -> 0.0010375382 | S10: 0
A11: 43567 | B11: ='Part 2 - CAPM 2.1, 2.2 and 2.3'!N11 -> 0.0039892588 | C11: ='Part 2 - CAPM 2.1, 2.2 and 2.3'!O11 -> -0.0064728258 | E11: 43567 | F11: 0.0631 | G11: =((1+F11)^(1/365))-1 -> 0.00016765561 | L11: =G11+($J$1*(B11)) -> 0.004165688 | M11: =G11+($J$1*(C11)) -> -0.0063194059 | O11: =P11+(Q11*(R11))+S11 -> 0.004165688 | P11: =G11 -> 0.00016765561 | Q11: =$J$1 -> 1.0021993 | R11: =B11 -> 0.0039892588 | S11: 0
A12: 43570 | B12: ='Part 2 - CAPM 2.1, 2.2 and 2.3'!N12 -> 0.0041632728 | C12: ='Part 2 - CAPM 2.1, 2.2 and 2.3'!O12 -> -0.0074646099 | E12: 43570 | F12: 0.0631 | G12: =((1+F12)^(1/365))-1 -> 0.00016765561 | L12: =G12+($J$1*(B12)) -> 0.0043400847 | M12: =G12+($J$1*(C12)) -> -0.0073133712 | O12: =P12+(Q12*(R12))+S12 -> 0.0043400847 | P12: =G12 -> 0.00016765561 | Q12: =$J$1 -> 1.0021993 | R12: =B12 -> 0.0041632728 | S12: 0
A13: 43571 | B13: ='Part 2 - CAPM 2.1, 2.2 and 2.3'!N13 -> 0.0065109311 | C13: ='Part 2 - CAPM 2.1, 2.2 and 2.3'!O13 -> 0.025398845 | E13: 43571 | F13: 0.0634 | G13: =((1+F13)^(1/365))-1 -> 0.00016842876 | L13: =G13+($J$1*(B13)) -> 0.0066936793 | M13: =G13+($J$1*(C13)) -> 0.025623133 | O13: =P13+(Q13*(R13))+S13 -> 0.0066936793 | P13: =G13 -> 0.00016842876 | Q13: =$J$1 -> 1.0021993 | R13: =B13 -> 0.0065109311 | S13: 0
A14: 43573 | B14: ='Part 2 - CAPM 2.1, 2.2 and 2.3'!N14 -> -0.004533857 | C14: ='Part 2 - CAPM 2.1, 2.2 and 2.3'!O14 -> 0.00076644191 | E14: 43573 | F14: 0.0634 | G14: =((1+F14)^(1/365))-1 -> 0.00016842876 | L14: =G14+($J$1*(B14)) -> -0.0043753996 | M14: =G14+($J$1*(C14)) -> 0.00093655631 | O14: =P14+(Q14*(R14))+S14 -> -0.0043753996 | P14: =G14 -> 0.00016842876 | Q14: =$J$1 -> 1.0021993 | R14: =B14 -> -0.004533857 | S14: 0
... A1213: 45379 | B1213: ='Part 2 - CAPM 2.1, 2.2 and 2.3'!N1213 -> 0.0081450317 | C1213: ='Part 2 - CAPM 2.1, 2.2 and 2.3'!O1213 -> 0.023882872 | E1213: 45379 | F1213: 0.0702 | G1213: =((1+F1213)^(1/365))-1 -> 0.00018589549 | L1213: =G1213+($J$1*(B1213)) -> 0.0083488406 | M1213: =G1213+($J$1*(C1213)) -> 0.024121293 | O1213: =P1213+(Q1213*(R1213))+S1213 -> 0.0083488406 | P1213: =G1213 -> 0.00018589549 | Q1213: =$J$1 -> 1.0021993 | R1213: =B1213 -> 0.0081450317 | S1213: 0
